Workbook

Sheet הסבר
A1: מיפוי מותאם – קליטה וניתוח
A2: בית ספר אורים · שאלונים לתלמידים בתפקוד סיעודי
A4: איך עובדים עם הקובץ
A5: 1. מה ממלאים | B5: רק את התאים הצהובים. התאים האפורים מחשבים לבד, לא כותבים בהם.
A6: 2. שורה אחת לכל מילוי | B6: כל פעם שתלמיד/ה ממלא/ת שאלון, מוסיפים שורה בגיליון הקליטה המתאים. שלושה מועדים = שלוש שורות.
A7: 3. רשימות נפתחות | B7: ברוב העמודות בוחרים מרשימה: כן / לא / לא ענה, ובתצפית 3 = הרבה, 2 = לפעמים, 1 = כמעט לא.
A8: 4. שורת הדוגמה | B8: השורה הראשונה בכל גיליון קליטה היא דוגמה (״תלמיד לדוגמה״). מוחקים אותה לפני שמתחילים.
A9: 5. גיליונות המעקב | B9: כותבים את שמות התלמידים בעמודה הצהובה. הנתונים לכל מועד מתמלאים לבד, לפי השם המדויק.
A10: 6. סיכום כיתתי | B10: כותבים את שמות הכיתות, והממוצעים לכל מועד מתמלאים לבד.
A12: מה כל מדד אומר
A13: מדד תצפית (1–3) | B13: ממוצע 9 שאלות התצפית של הצוות. זה המדד המרכזי לרווחה ולהשתתפות. 3 = רואים את זה הרבה.
A14: תשובות התלמיד/ה (%) | B14: כמה ״כן״ מתוך השאלות שהתלמיד/ה ענה/תה עליהן. מבטא איך התלמיד/ה מרגיש/ה עכשיו, לא דימוי עצמי.
A15: התאמה בחימום | B15: האם התלמיד/ה ענה/תה על שאלות החימום כמו שהצוות ציפה. ״תואם״ = אפשר לסמוך יותר על התשובות.
A16: אמינות המילוי | B16: ״אמין״ אם החימום תואם וההבנה לא סומנה ״לא ברור״. בסוף השנה כדאי לנתח בנפרד רק מילויים אמינים.
A17: שינוי בתצפית | B17: ההפרש בין סוף שנה לתחילת שנה. שינוי של חצי נקודה ומעלה (על סולם 1–3) הוא כלל אצבע לשינוי שכדאי לשים לב אליו, לא סף סטטיסטי.
A18: זיהוי עצמי (״זה אני״) | B18: מלא = בחר/ה בתמונה של עצמו/ה, ענה/תה ״כן״ על התמונה שלו/ה ו״לא״ על התמונה האחרת.
A19: דיוק ״אני יכול/ה״ | B19: כמה מהתשובות של התלמיד/ה תואמות את מה שהצוות רואה. ״חלקית״ נספרת כחצי.
A20: הערכת יתר / חסר | B20: יתר = אמר/ה ״כן״ והצוות סימן ״לא״. חסר = אמר/ה ״לא״ והצוות סימן ״כן״.
A21: רמה שהושגה (0–3) | B21: 0 = עדיין אין זיהוי עצמי מלא · 1 = זיהוי עצמי · 2 = גם דיוק של 60% ומעלה ב״אני יכול/ה״ · 3 = גם ״כן״ על לפחות 2 שאלות גאווה ושייכות ותצפית גאווה 2 ומעלה.
A23: הערה | B23: הספים (חצי נקודה, 60%) נקבעו לשנה הראשונה כנקודת פתיחה סבירה. אפשר לשנות אותם אחרי שיהיו נתונים מסוף השנה.
A26: מקרא צבעים
A27: למילוי | B27: תא שממלאים
A28: מחושב | B28: נוסחה, לא לגעת

Sheet רווחה - קליטה
A1: מיפוי רווחה והשתתפות – קליטה
A2: שורה לכל מילוי. ממלאים רק תאים צהובים. השורה הראשונה היא דוגמה, מוחקים אותה.
A3: פרטי המילוי | H3: חימום | L3: תשובות התלמיד/ה | U3: תצפית הצוות (3 = הרבה · 2 = לפעמים · 1 = כמעט לא) | AE3: חישובים אוטומטיים
A4: שם התלמיד/ה | B4: כיתה | C4: מועד | D4: תאריך | E4: ממלא/ת | F4: אופן תשובה | G4: הבנת השאלות | H4: מוזיקה – צפוי | I4: מוזיקה – תשובה | J4: בועות – צפוי | K4: בועות – תשובה | L4: להיות עם הילדים | M4: שמח/ה כשמדברים איתי | N4: אוהב/ת את הפעילויות | O4: אוהב/ת לשחק ולנסות | P4: רגוע ונעים לי | Q4: אוהב/ת לבחור בעצמי | R4: אוהב/ת לעזור ולהשתתף | S4: המבוגרים נחמדים | T4: אוהב/ת להגיע | U4: מגיב/ה לקרבה | V4: יוזם/ת קשר | W4: מתעניין/ת בפעילות | X4: מעורב/ת לאורך זמן | Y4: רגוע/ה ונינוח/ה | Z4: מביע/ה אי־נוחות מובנת | AA4: מביע/ה בחירה | AB4: משתתף/ת ביומיום | AC4: שמח/ה בבוקר | AD4: הערות | AE4: מפתח | AF4: חברתי – תלמיד | AG4: למידה – תלמיד | AH4: רגשי – תלמיד | AI4: השתתפות – תלמיד | AJ4: בית הספר – תלמיד | AK4: תלמיד – סה״כ ״כן״ | AL4: תצפית חברתי | AM4: תצפית למידה | AN4: תצפית רגשי | AO4: תצפית השתתפות | AP4: תצפית אקלים | AQ4: מדד תצפית כולל | AR4: התאמה בחימום | AS4: אמינות המילוי
A5: תלמיד לדוגמה | B5: כיתה לדוגמה | C5: תחילת שנה | D5: 11/11/2026 | E5: נופר | F5: מבט | G5: הבין/ה | H5: כן | I5: כן | J5: לא | K5: לא | L5: כן | M5: כן | N5: כן | O5: לא | P5: כן | Q5: לא | R5: לא ענה | S5: כן | T5: כן | U5: 2 | V5: 1 | W5: 3 | X5: 2 | Y5: 2 | Z5: 3 | AA5: 1 | AB5: 2 | AC5: 3 | AD5: דוגמה – למחוק | AE5: =IF($A5="","",$A5&"|"&$C5) -> תלמיד לדוגמה|תחילת שנה | AF5: =IF($A5="","",IFERROR(COUNTIF(L5:M5,"כן")/(COUNTIF(L5:M5,"כן")+COUNTIF(L5:M5,"לא")),"")) -> 1 | AG5: =IF($A5="","",IFERROR(COUNTIF(N5:O5,"כן")/(COUNTIF(N5:O5,"כן")+COUNTIF(N5:O5,"לא")),"")) -> 0.5 | AH5: =IF($A5="","",IFERROR(COUNTIF(P5,"כן")/(COUNTIF(P5,"כן")+COUNTIF(P5,"לא")),"")) -> 1 | AI5: =IF($A5="","",IFERROR(COUNTIF(Q5:R5,"כן")/(COUNTIF(Q5:R5,"כן")+COUNTIF(Q5:R5,"לא")),"")) -> 0 | AJ5: =IF($A5="","",IFERROR(COUNTIF(S5:T5,"כן")/(COUNTIF(S5:T5,"כן")+COUNTIF(S5:T5,"לא")),"")) -> 1 | AK5: =IF($A5="","",IFERROR(COUNTIF(L5:T5,"כן")/(COUNTIF(L5:T5,"כן")+COUNTIF(L5:T5,"לא")),"")) -> 0.75 | AL5: =IF($A5="","",IFERROR(AVERAGE(U5:V5),"")) -> 1.5 | AM5: =IF($A5="","",IFERROR(AVERAGE(W5:X5),"")) -> 2.5 | AN5: =IF($A5="","",IFERROR(AVERAGE(Y5:Z5),"")) -> 2.5 | AO5: =IF($A5="","",IFERROR(AVERAGE(AA5:AB5),"")) -> 1.5 | AP5: =IF($A5="","",IFERROR(AVERAGE(AC5),"")) -> 3 | AQ5: =IF($A5="","",IFERROR(AVERAGE(U5:AC5),"")) -> 2.1111111 | AR5: =IF($A5="","",IF(AND(H5="",J5=""),"לא נבדק",IF(AND(OR(H5="",H5=I5),OR(J5="",J5=K5)),"תואם","לא תואם"))) -> תואם | AS5: =IF($A5="","",IF(AND(AR5<>"לא תואם",G5<>"לא ברור"),"אמין","לפרש בזהירות")) -> אמין
AE6: =IF($A6="","",$A6&"|"&$C6) | AF6: =IF($A6="","",IFERROR(COUNTIF(L6:M6,"כן")/(COUNTIF(L6:M6,"כן")+COUNTIF(L6:M6,"לא")),"")) | AG6: =IF($A6="","",IFERROR(COUNTIF(N6:O6,"כן")/(COUNTIF(N6:O6,"כן")+COUNTIF(N6:O6,"לא")),"")) | AH6: =IF($A6="","",IFERROR(COUNTIF(P6,"כן")/(COUNTIF(P6,"כן")+COUNTIF(P6,"לא")),"")) | AI6: =IF($A6="","",IFERROR(COUNTIF(Q6:R6,"כן")/(COUNTIF(Q6:R6,"כן")+COUNTIF(Q6:R6,"לא")),"")) | AJ6: =IF($A6="","",IFERROR(COUNTIF(S6:T6,"כן")/(COUNTIF(S6:T6,"כן")+COUNTIF(S6:T6,"לא")),"")) | AK6: =IF($A6="","",IFERROR(COUNTIF(L6:T6,"כן")/(COUNTIF(L6:T6,"כן")+COUNTIF(L6:T6,"לא")),"")) | AL6: =IF($A6="","",IFERROR(AVERAGE(U6:V6),"")) | AM6: =IF($A6="","",IFERROR(AVERAGE(W6:X6),"")) | AN6: =IF($A6="","",IFERROR(AVERAGE(Y6:Z6),"")) | AO6: =IF($A6="","",IFERROR(AVERAGE(AA6:AB6),"")) | AP6: =IF($A6="","",IFERROR(AVERAGE(AC6),"")) | AQ6: =IF($A6="","",IFERROR(AVERAGE(U6:AC6),"")) | AR6: =IF($A6="","",IF(AND(H6="",J6=""),"לא נבדק",IF(AND(OR(H6="",H6=I6),OR(J6="",J6=K6)),"תואם","לא תואם"))) | AS6: =IF($A6="","",IF(AND(AR6<>"לא תואם",G6<>"לא ברור"),"אמין","לפרש בזהירות"))
AE7: =IF($A7="","",$A7&"|"&$C7) | AF7: =IF($A7="","",IFERROR(COUNTIF(L7:M7,"כן")/(COUNTIF(L7:M7,"כן")+COUNTIF(L7:M7,"לא")),"")) | AG7: =IF($A7="","",IFERROR(COUNTIF(N7:O7,"כן")/(COUNTIF(N7:O7,"כן")+COUNTIF(N7:O7,"לא")),"")) | AH7: =IF($A7="","",IFERROR(COUNTIF(P7,"כן")/(COUNTIF(P7,"כן")+COUNTIF(P7,"לא")),"")) | AI7: =IF($A7="","",IFERROR(COUNTIF(Q7:R7,"כן")/(COUNTIF(Q7:R7,"כן")+COUNTIF(Q7:R7,"לא")),"")) | AJ7: =IF($A7="","",IFERROR(COUNTIF(S7:T7,"כן")/(COUNTIF(S7:T7,"כן")+COUNTIF(S7:T7,"לא")),"")) | AK7: =IF($A7="","",IFERROR(COUNTIF(L7:T7,"כן")/(COUNTIF(L7:T7,"כן")+COUNTIF(L7:T7,"לא")),"")) | AL7: =IF($A7="","",IFERROR(AVERAGE(U7:V7),"")) | AM7: =IF($A7="","",IFERROR(AVERAGE(W7:X7),"")) | AN7: =IF($A7="","",IFERROR(AVERAGE(Y7:Z7),"")) | AO7: =IF($A7="","",IFERROR(AVERAGE(AA7:AB7),"")) | AP7: =IF($A7="","",IFERROR(AVERAGE(AC7),"")) | AQ7: =IF($A7="","",IFERROR(AVERAGE(U7:AC7),"")) | AR7: =IF($A7="","",IF(AND(H7="",J7=""),"לא נבדק",IF(AND(OR(H7="",H7=I7),OR(J7="",J7=K7)),"תואם","לא תואם"))) | AS7: =IF($A7="","",IF(AND(AR7<>"לא תואם",G7<>"לא ברור"),"אמין","לפרש בזהירות"))
AE8: =IF($A8="","",$A8&"|"&$C8) | AF8: =IF($A8="","",IFERROR(COUNTIF(L8:M8,"כן")/(COUNTIF(L8:M8,"כן")+COUNTIF(L8:M8,"לא")),"")) | AG8: =IF($A8="","",IFERROR(COUNTIF(N8:O8,"כן")/(COUNTIF(N8:O8,"כן")+COUNTIF(N8:O8,"לא")),"")) | AH8: =IF($A8="","",IFERROR(COUNTIF(P8,"כן")/(COUNTIF(P8,"כן")+COUNTIF(P8,"לא")),"")) | AI8: =IF($A8="","",IFERROR(COUNTIF(Q8:R8,"כן")/(COUNTIF(Q8:R8,"כן")+COUNTIF(Q8:R8,"לא")),"")) | AJ8: =IF($A8="","",IFERROR(COUNTIF(S8:T8,"כן")/(COUNTIF(S8:T8,"כן")+COUNTIF(S8:T8,"לא")),"")) | AK8: =IF($A8="","",IFERROR(COUNTIF(L8:T8,"כן")/(COUNTIF(L8:T8,"כן")+COUNTIF(L8:T8,"לא")),"")) | AL8: =IF($A8="","",IFERROR(AVERAGE(U8:V8),"")) | AM8: =IF($A8="","",IFERROR(AVERAGE(W8:X8),"")) | AN8: =IF($A8="","",IFERROR(AVERAGE(Y8:Z8),"")) | AO8: =IF($A8="","",IFERROR(AVERAGE(AA8:AB8),"")) | AP8: =IF($A8="","",IFERROR(AVERAGE(AC8),"")) | AQ8: =IF($A8="","",IFERROR(AVERAGE(U8:AC8),"")) | AR8: =IF($A8="","",IF(AND(H8="",J8=""),"לא נבדק",IF(AND(OR(H8="",H8=I8),OR(J8="",J8=K8)),"תואם","לא תואם"))) | AS8: =IF($A8="","",IF(AND(AR8<>"לא תואם",G8<>"לא ברור"),"אמין","לפרש בזהירות"))
AE9: =IF($A9="","",$A9&"|"&$C9) | AF9: =IF($A9="","",IFERROR(COUNTIF(L9:M9,"כן")/(COUNTIF(L9:M9,"כן")+COUNTIF(L9:M9,"לא")),"")) | AG9: =IF($A9="","",IFERROR(COUNTIF(N9:O9,"כן")/(COUNTIF(N9:O9,"כן")+COUNTIF(N9:O9,"לא")),"")) | AH9: =IF($A9="","",IFERROR(COUNTIF(P9,"כן")/(COUNTIF(P9,"כן")+COUNTIF(P9,"לא")),"")) | AI9: =IF($A9="","",IFERROR(COUNTIF(Q9:R9,"כן")/(COUNTIF(Q9:R9,"כן")+COUNTIF(Q9:R9,"לא")),"")) | AJ9: =IF($A9="","",IFERROR(COUNTIF(S9:T9,"כן")/(COUNTIF(S9:T9,"כן")+COUNTIF(S9:T9,"לא")),"")) | AK9: =IF($A9="","",IFERROR(COUNTIF(L9:T9,"כן")/(COUNTIF(L9:T9,"כן")+COUNTIF(L9:T9,"לא")),"")) | AL9: =IF($A9="","",IFERROR(AVERAGE(U9:V9),"")) | AM9: =IF($A9="","",IFERROR(AVERAGE(W9:X9),"")) | AN9: =IF($A9="","",IFERROR(AVERAGE(Y9:Z9),"")) | AO9: =IF($A9="","",IFERROR(AVERAGE(AA9:AB9),"")) | AP9: =IF($A9="","",IFERROR(AVERAGE(AC9),"")) | AQ9: =IF($A9="","",IFERROR(AVERAGE(U9:AC9),"")) | AR9: =IF($A9="","",IF(AND(H9="",J9=""),"לא נבדק",IF(AND(OR(H9="",H9=I9),OR(J9="",J9=K9)),"תואם","לא תואם"))) | AS9: =IF($A9="","",IF(AND(AR9<>"לא תואם",G9<>"לא ברור"),"אמין","לפרש בזהירות"))
AE10: =IF($A10="","",$A10&"|"&$C10) | AF10: =IF($A10="","",IFERROR(COUNTIF(L10:M10,"כן")/(COUNTIF(L10:M10,"כן")+COUNTIF(L10:M10,"לא")),"")) | AG10: =IF($A10="","",IFERROR(COUNTIF(N10:O10,"כן")/(COUNTIF(N10:O10,"כן")+COUNTIF(N10:O10,"לא")),"")) | AH10: =IF($A10="","",IFERROR(COUNTIF(P10,"כן")/(COUNTIF(P10,"כן")+COUNTIF(P10,"לא")),"")) | AI10: =IF($A10="","",IFERROR(COUNTIF(Q10:R10,"כן")/(COUNTIF(Q10:R10,"כן")+COUNTIF(Q10:R10,"לא")),"")) | AJ10: =IF($A10="","",IFERROR(COUNTIF(S10:T10,"כן")/(COUNTIF(S10:T10,"כן")+COUNTIF(S10:T10,"לא")),"")) | AK10: =IF($A10="","",IFERROR(COUNTIF(L10:T10,"כן")/(COUNTIF(L10:T10,"כן")+COUNTIF(L10:T10,"לא")),"")) | AL10: =IF($A10="","",IFERROR(AVERAGE(U10:V10),"")) | AM10: =IF($A10="","",IFERROR(AVERAGE(W10:X10),"")) | AN10: =IF($A10="","",IFERROR(AVERAGE(Y10:Z10),"")) | AO10: =IF($A10="","",IFERROR(AVERAGE(AA10:AB10),"")) | AP10: =IF($A10="","",IFERROR(AVERAGE(AC10),"")) | AQ10: =IF($A10="","",IFERROR(AVERAGE(U10:AC10),"")) | AR10: =IF($A10="","",IF(AND(H10="",J10=""),"לא נבדק",IF(AND(OR(H10="",H10=I10),OR(J10="",J10=K10)),"תואם","לא תואם"))) | AS10: =IF($A10="","",IF(AND(AR10<>"לא תואם",G10<>"לא ברור"),"אמין","לפרש בזהירות"))
AE11: =IF($A11="","",$A11&"|"&$C11) | AF11: =IF($A11="","",IFERROR(COUNTIF(L11:M11,"כן")/(COUNTIF(L11:M11,"כן")+COUNTIF(L11:M11,"לא")),"")) | AG11: =IF($A11="","",IFERROR(COUNTIF(N11:O11,"כן")/(COUNTIF(N11:O11,"כן")+COUNTIF(N11:O11,"לא")),"")) | AH11: =IF($A11="","",IFERROR(COUNTIF(P11,"כן")/(COUNTIF(P11,"כן")+COUNTIF(P11,"לא")),"")) | AI11: =IF($A11="","",IFERROR(COUNTIF(Q11:R11,"כן")/(COUNTIF(Q11:R11,"כן")+COUNTIF(Q11:R11,"לא")),"")) | AJ11: =IF($A11="","",IFERROR(COUNTIF(S11:T11,"כן")/(COUNTIF(S11:T11,"כן")+COUNTIF(S11:T11,"לא")),"")) | AK11: =IF($A11="","",IFERROR(COUNTIF(L11:T11,"כן")/(COUNTIF(L11:T11,"כן")+COUNTIF(L11:T11,"לא")),"")) | AL11: =IF($A11="","",IFERROR(AVERAGE(U11:V11),"")) | AM11: =IF($A11="","",IFERROR(AVERAGE(W11:X11),"")) | AN11: =IF($A11="","",IFERROR(AVERAGE(Y11:Z11),"")) | AO11: =IF($A11="","",IFERROR(AVERAGE(AA11:AB11),"")) | AP11: =IF($A11="","",IFERROR(AVERAGE(AC11),"")) | AQ11: =IF($A11="","",IFERROR(AVERAGE(U11:AC11),"")) | AR11: =IF($A11="","",IF(AND(H11="",J11=""),"לא נבדק",IF(AND(OR(H11="",H11=I11),OR(J11="",J11=K11)),"תואם","לא תואם"))) | AS11: =IF($A11="","",IF(AND(AR11<>"לא תואם",G11<>"לא ברור"),"אמין","לפרש בזהירות"))
AE12: =IF($A12="","",$A12&"|"&$C12) | AF12: =IF($A12="","",IFERROR(COUNTIF(L12:M12,"כן")/(COUNTIF(L12:M12,"כן")+COUNTIF(L12:M12,"לא")),"")) | AG12: =IF($A12="","",IFERROR(COUNTIF(N12:O12,"כן")/(COUNTIF(N12:O12,"כן")+COUNTIF(N12:O12,"לא")),"")) | AH12: =IF($A12="","",IFERROR(COUNTIF(P12,"כן")/(COUNTIF(P12,"כן")+COUNTIF(P12,"לא")),"")) | AI12: =IF($A12="","",IFERROR(COUNTIF(Q12:R12,"כן")/(COUNTIF(Q12:R12,"כן")+COUNTIF(Q12:R12,"לא")),"")) | AJ12: =IF($A12="","",IFERROR(COUNTIF(S12:T12,"כן")/(COUNTIF(S12:T12,"כן")+COUNTIF(S12:T12,"לא")),"")) | AK12: =IF($A12="","",IFERROR(COUNTIF(L12:T12,"כן")/(COUNTIF(L12:T12,"כן")+COUNTIF(L12:T12,"לא")),"")) | AL12: =IF($A12="","",IFERROR(AVERAGE(U12:V12),"")) | AM12: =IF($A12="","",IFERROR(AVERAGE(W12:X12),"")) | AN12: =IF($A12="","",IFERROR(AVERAGE(Y12:Z12),"")) | AO12: =IF($A12="","",IFERROR(AVERAGE(AA12:AB12),"")) | AP12: =IF($A12="","",IFERROR(AVERAGE(AC12),"")) | AQ12: =IF($A12="","",IFERROR(AVERAGE(U12:AC12),"")) | AR12: =IF($A12="","",IF(AND(H12="",J12=""),"לא נבדק",IF(AND(OR(H12="",H12=I12),OR(J12="",J12=K12)),"תואם","לא תואם"))) | AS12: =IF($A12="","",IF(AND(AR12<>"לא תואם",G12<>"לא ברור"),"אמין","לפרש בזהירות"))
AE13: =IF($A13="","",$A13&"|"&$C13) | AF13: =IF($A13="","",IFERROR(COUNTIF(L13:M13,"כן")/(COUNTIF(L13:M13,"כן")+COUNTIF(L13:M13,"לא")),"")) | AG13: =IF($A13="","",IFERROR(COUNTIF(N13:O13,"כן")/(COUNTIF(N13:O13,"כן")+COUNTIF(N13:O13,"לא")),"")) | AH13: =IF($A13="","",IFERROR(COUNTIF(P13,"כן")/(COUNTIF(P13,"כן")+COUNTIF(P13,"לא")),"")) | AI13: =IF($A13="","",IFERROR(COUNTIF(Q13:R13,"כן")/(COUNTIF(Q13:R13,"כן")+COUNTIF(Q13:R13,"לא")),"")) | AJ13: =IF($A13="","",IFERROR(COUNTIF(S13:T13,"כן")/(COUNTIF(S13:T13,"כן")+COUNTIF(S13:T13,"לא")),"")) | AK13: =IF($A13="","",IFERROR(COUNTIF(L13:T13,"כן")/(COUNTIF(L13:T13,"כן")+COUNTIF(L13:T13,"לא")),"")) | AL13: =IF($A13="","",IFERROR(AVERAGE(U13:V13),"")) | AM13: =IF($A13="","",IFERROR(AVERAGE(W13:X13),"")) | AN13: =IF($A13="","",IFERROR(AVERAGE(Y13:Z13),"")) | AO13: =IF($A13="","",IFERROR(AVERAGE(AA13:AB13),"")) | AP13: =IF($A13="","",IFERROR(AVERAGE(AC13),"")) | AQ13: =IF($A13="","",IFERROR(AVERAGE(U13:AC13),"")) | AR13: =IF($A13="","",IF(AND(H13="",J13=""),"לא נבדק",IF(AND(OR(H13="",H13=I13),OR(J13="",J13=K13)),"תואם","לא תואם"))) | AS13: =IF($A13="","",IF(AND(AR13<>"לא תואם",G13<>"לא ברור"),"אמין","לפרש בזהירות"))
AE14: =IF($A14="","",$A14&"|"&$C14) | AF14: =IF($A14="","",IFERROR(COUNTIF(L14:M14,"כן")/(COUNTIF(L14:M14,"כן")+COUNTIF(L14:M14,"לא")),"")) | AG14: =IF($A14="","",IFERROR(COUNTIF(N14:O14,"כן")/(COUNTIF(N14:O14,"כן")+COUNTIF(N14:O14,"לא")),"")) | AH14: =IF($A14="","",IFERROR(COUNTIF(P14,"כן")/(COUNTIF(P14,"כן")+COUNTIF(P14,"לא")),"")) | AI14: =IF($A14="","",IFERROR(COUNTIF(Q14:R14,"כן")/(COUNTIF(Q14:R14,"כן")+COUNTIF(Q14:R14,"לא")),"")) | AJ14: =IF($A14="","",IFERROR(COUNTIF(S14:T14,"כן")/(COUNTIF(S14:T14,"כן")+COUNTIF(S14:T14,"לא")),"")) | AK14: =IF($A14="","",IFERROR(COUNTIF(L14:T14,"כן")/(COUNTIF(L14:T14,"כן")+COUNTIF(L14:T14,"לא")),"")) | AL14: =IF($A14="","",IFERROR(AVERAGE(U14:V14),"")) | AM14: =IF($A14="","",IFERROR(AVERAGE(W14:X14),"")) | AN14: =IF($A14="","",IFERROR(AVERAGE(Y14:Z14),"")) | AO14: =IF($A14="","",IFERROR(AVERAGE(AA14:AB14),"")) | AP14: =IF($A14="","",IFERROR(AVERAGE(AC14),"")) | AQ14: =IF($A14="","",IFERROR(AVERAGE(U14:AC14),"")) | AR14: =IF($A14="","",IF(AND(H14="",J14=""),"לא נבדק",IF(AND(OR(H14="",H14=I14),OR(J14="",J14=K14)),"תואם","לא תואם"))) | AS14: =IF($A14="","",IF(AND(AR14<>"לא תואם",G14<>"לא ברור"),"אמין","לפרש בזהירות"))
AE15: =IF($A15="","",$A15&"|"&$C15) | AF15: =IF($A15="","",IFERROR(COUNTIF(L15:M15,"כן")/(COUNTIF(L15:M15,"כן")+COUNTIF(L15:M15,"לא")),"")) | AG15: =IF($A15="","",IFERROR(COUNTIF(N15:O15,"כן")/(COUNTIF(N15:O15,"כן")+COUNTIF(N15:O15,"לא")),"")) | AH15: =IF($A15="","",IFERROR(COUNTIF(P15,"כן")/(COUNTIF(P15,"כן")+COUNTIF(P15,"לא")),"")) | AI15: =IF($A15="","",IFERROR(COUNTIF(Q15:R15,"כן")/(COUNTIF(Q15:R15,"כן")+COUNTIF(Q15:R15,"לא")),"")) | AJ15: =IF($A15="","",IFERROR(COUNTIF(S15:T15,"כן")/(COUNTIF(S15:T15,"כן")+COUNTIF(S15:T15,"לא")),"")) | AK15: =IF($A15="","",IFERROR(COUNTIF(L15:T15,"כן")/(COUNTIF(L15:T15,"כן")+COUNTIF(L15:T15,"לא")),"")) | AL15: =IF($A15="","",IFERROR(AVERAGE(U15:V15),"")) | AM15: =IF($A15="","",IFERROR(AVERAGE(W15:X15),"")) | AN15: =IF($A15="","",IFERROR(AVERAGE(Y15:Z15),"")) | AO15: =IF($A15="","",IFERROR(AVERAGE(AA15:AB15),"")) | AP15: =IF($A15="","",IFERROR(AVERAGE(AC15),"")) | AQ15: =IF($A15="","",IFERROR(AVERAGE(U15:AC15),"")) | AR15: =IF($A15="","",IF(AND(H15="",J15=""),"לא נבדק",IF(AND(OR(H15="",H15=I15),OR(J15="",J15=K15)),"תואם","לא תואם"))) | AS15: =IF($A15="","",IF(AND(AR15<>"לא תואם",G15<>"לא ברור"),"אמין","לפרש בזהירות"))
AE16: =IF($A16="","",$A16&"|"&$C16) | AF16: =IF($A16="","",IFERROR(COUNTIF(L16:M16,"כן")/(COUNTIF(L16:M16,"כן")+COUNTIF(L16:M16,"לא")),"")) | AG16: =IF($A16="","",IFERROR(COUNTIF(N16:O16,"כן")/(COUNTIF(N16:O16,"כן")+COUNTIF(N16:O16,"לא")),"")) | AH16: =IF($A16="","",IFERROR(COUNTIF(P16,"כן")/(COUNTIF(P16,"כן")+COUNTIF(P16,"לא")),"")) | AI16: =IF($A16="","",IFERROR(COUNTIF(Q16:R16,"כן")/(COUNTIF(Q16:R16,"כן")+COUNTIF(Q16:R16,"לא")),"")) | AJ16: =IF($A16="","",IFERROR(COUNTIF(S16:T16,"כן")/(COUNTIF(S16:T16,"כן")+COUNTIF(S16:T16,"לא")),"")) | AK16: =IF($A16="","",IFERROR(COUNTIF(L16:T16,"כן")/(COUNTIF(L16:T16,"כן")+COUNTIF(L16:T16,"לא")),"")) | AL16: =IF($A16="","",IFERROR(AVERAGE(U16:V16),"")) | AM16: =IF($A16="","",IFERROR(AVERAGE(W16:X16),"")) | AN16: =IF($A16="","",IFERROR(AVERAGE(Y16:Z16),"")) | AO16: =IF($A16="","",IFERROR(AVERAGE(AA16:AB16),"")) | AP16: =IF($A16="","",IFERROR(AVERAGE(AC16),"")) | AQ16: =IF($A16="","",IFERROR(AVERAGE(U16:AC16),"")) | AR16: =IF($A16="","",IF(AND(H16="",J16=""),"לא נבדק",IF(AND(OR(H16="",H16=I16),OR(J16="",J16=K16)),"תואם","לא תואם"))) | AS16: =IF($A16="","",IF(AND(AR16<>"לא תואם",G16<>"לא ברור"),"אמין","לפרש בזהירות"))
AE17: =IF($A17="","",$A17&"|"&$C17) | AF17: =IF($A17="","",IFERROR(COUNTIF(L17:M17,"כן")/(COUNTIF(L17:M17,"כן")+COUNTIF(L17:M17,"לא")),"")) | AG17: =IF($A17="","",IFERROR(COUNTIF(N17:O17,"כן")/(COUNTIF(N17:O17,"כן")+COUNTIF(N17:O17,"לא")),"")) | AH17: =IF($A17="","",IFERROR(COUNTIF(P17,"כן")/(COUNTIF(P17,"כן")+COUNTIF(P17,"לא")),"")) | AI17: =IF($A17="","",IFERROR(COUNTIF(Q17:R17,"כן")/(COUNTIF(Q17:R17,"כן")+COUNTIF(Q17:R17,"לא")),"")) | AJ17: =IF($A17="","",IFERROR(COUNTIF(S17:T17,"כן")/(COUNTIF(S17:T17,"כן")+COUNTIF(S17:T17,"לא")),"")) | AK17: =IF($A17="","",IFERROR(COUNTIF(L17:T17,"כן")/(COUNTIF(L17:T17,"כן")+COUNTIF(L17:T17,"לא")),"")) | AL17: =IF($A17="","",IFERROR(AVERAGE(U17:V17),"")) | AM17: =IF($A17="","",IFERROR(AVERAGE(W17:X17),"")) | AN17: =IF($A17="","",IFERROR(AVERAGE(Y17:Z17),"")) | AO17: =IF($A17="","",IFERROR(AVERAGE(AA17:AB17),"")) | AP17: =IF($A17="","",IFERROR(AVERAGE(AC17),"")) | AQ17: =IF($A17="","",IFERROR(AVERAGE(U17:AC17),"")) | AR17: =IF($A17="","",IF(AND(H17="",J17=""),"לא נבדק",IF(AND(OR(H17="",H17=I17),OR(J17="",J17=K17)),"תואם","לא תואם"))) | AS17: =IF($A17="","",IF(AND(AR17<>"לא תואם",G17<>"לא ברור"),"אמין","לפרש בזהירות"))
... AE204: =IF($A204="","",$A204&"|"&$C204) | AF204: =IF($A204="","",IFERROR(COUNTIF(L204:M204,"כן")/(COUNTIF(L204:M204,"כן")+COUNTIF(L204:M204,"לא")),"")) | AG204: =IF($A204="","",IFERROR(COUNTIF(N204:O204,"כן")/(COUNTIF(N204:O204,"כן")+COUNTIF(N204:O204,"לא")),"")) | AH204: =IF($A204="","",IFERROR(COUNTIF(P204,"כן")/(COUNTIF(P204,"כן")+COUNTIF(P204,"לא")),"")) | AI204: =IF($A204="","",IFERROR(COUNTIF(Q204:R204,"כן")/(COUNTIF(Q204:R204,"כן")+COUNTIF(Q204:R204,"לא")),"")) | AJ204: =IF($A204="","",IFERROR(COUNTIF(S204:T204,"כן")/(COUNTIF(S204:T204,"כן")+COUNTIF(S204:T204,"לא")),"")) | AK204: =IF($A204="","",IFERROR(COUNTIF(L204:T204,"כן")/(COUNTIF(L204:T204,"כן")+COUNTIF(L204:T204,"לא")),"")) | AL204: =IF($A204="","",IFERROR(AVERAGE(U204:V204),"")) | AM204: =IF($A204="","",IFERROR(AVERAGE(W204:X204),"")) | AN204: =IF($A204="","",IFERROR(AVERAGE(Y204:Z204),"")) | AO204: =IF($A204="","",IFERROR(AVERAGE(AA204:AB204),"")) | AP204: =IF($A204="","",IFERROR(AVERAGE(AC204),"")) | AQ204: =IF($A204="","",IFERROR(AVERAGE(U204:AC204),"")) | AR204: =IF($A204="","",IF(AND(H204="",J204=""),"לא נבדק",IF(AND(OR(H204="",H204=I204),OR(J204="",J204=K204)),"תואם","לא תואם"))) | AS204: =IF($A204="","",IF(AND(AR204<>"לא תואם",G204<>"לא ברור"),"אמין","לפרש בזהירות"))

Sheet זה אני - קליטה
A1: ״זה אני״ – קליטה
A2: שורה לכל מילוי. ממלאים רק תאים צהובים. השורה הראשונה היא דוגמה, מוחקים אותה.
A3: פרטי המילוי | H3: זיהוי עצמי | K3: אני יכול/ה – תשובת התלמיד/ה | P3: האם זה נכון? – בדיקת הצוות | U3: גאווה ושייכות | Z3: חישובים אוטומטיים
A4: שם התלמיד/ה | B4: כיתה | C4: מועד | D4: תאריך | E4: ממלא/ת | F4: אופן תשובה | G4: הבנת השאלות | H4: איפה אני? (בחירת תמונה) | I4: זה אני? (התמונה שלו/ה) | J4: זה אני? (תמונה אחרת) | K4: תלמיד/ה: להגיד שלום | L4: תלמיד/ה: לבחור מה אני רוצה | M4: תלמיד/ה: להפעיל מתג או מסך | N4: תלמיד/ה: לעזור באוכל או בלבוש | O4: תלמיד/ה: להראות שאני שמח/ה | P4: צוות: להגיד שלום | Q4: צוות: לבחור מה אני רוצה | R4: צוות: להפעיל מתג או מסך | S4: צוות: לעזור באוכל או בלבוש | T4: צוות: להראות שאני שמח/ה | U4: את זה אני עשיתי | V4: זה יפה | W4: זו הכיתה שלי | X4: תצפית: מראה גאווה (3/2/1) | Y4: הערות | Z4: מפתח | AA4: זיהוי עצמי | AB4: ״אני יכול/ה״ – כן | AC4: דיוק ״אני יכול/ה״ | AD4: הערכת יתר | AE4: הערכת חסר | AF4: גאווה ושייכות – כן | AG4: רמה שהושגה (0–3)
A5: תלמיד לדוגמה | B5: כיתה לדוגמה | C5: תחילת שנה | D5: 11/11/2026 | E5: נופר | F5: מגע או לחיצה | G5: חלקית | H5: בחר/ה בעצמו/ה | I5: כן | J5: לא | K5: כן | L5: כן | M5: לא | N5: כן | O5: כן | P5: כן | Q5: חלקית | R5: כן | S5: לא | T5: כן | U5: כן | V5: כן | W5: לא ענה | X5: 2 | Y5: דוגמה – למחוק | Z5: =IF($A5="","",$A5&"|"&$C5) -> תלמיד לדוגמה|תחילת שנה | AA5: =IF($A5="","",IF(OR(H5="לא נבדק",H5=""),"לא נבדק",IF(AND(H5="בחר/ה בעצמו/ה",I5="כן",J5="לא"),"מלא",IF(OR(H5="בחר/ה בעצמו/ה",I5="כן"),"חלקי","עדיין לא")))) -> מלא | AB5: =IF($A5="","",COUNTIF(K5:O5,"כן")) -> 4 | AC5: =IF($A5="","",IFERROR(SUMPRODUCT((K5:O5="כן")*(P5:T5="כן")+(K5:O5="לא")*(P5:T5="לא")+0.5*(P5:T5="חלקית")*((K5:O5="כן")+(K5:O5="לא")))/SUMPRODUCT(((K5:O5="כן")+(K5:O5="לא"))*(P5:T5<>"")),"")) -> 0.5 | AD5: =IF($A5="","",SUMPRODUCT((K5:O5="כן")*(P5:T5="לא"))) -> 1 | AE5: =IF($A5="","",SUMPRODUCT((K5:O5="לא")*(P5:T5="כן"))) -> 1 | AF5: =IF($A5="","",COUNTIF(U5:W5,"כן")) -> 2 | AG5: =IF($A5="","",IF(AA5<>"מלא",0,IF(OR(AC5="",N(AC5)<0.6),1,IF(AND(AF5>=2,N(X5)>=2),3,2)))) -> 1
Z6: =IF($A6="","",$A6&"|"&$C6) | AA6: =IF($A6="","",IF(OR(H6="לא נבדק",H6=""),"לא נבדק",IF(AND(H6="בחר/ה בעצמו/ה",I6="כן",J6="לא"),"מלא",IF(OR(H6="בחר/ה בעצמו/ה",I6="כן"),"חלקי","עדיין לא")))) | AB6: =IF($A6="","",COUNTIF(K6:O6,"כן")) | AC6: =IF($A6="","",IFERROR(SUMPRODUCT((K6:O6="כן")*(P6:T6="כן")+(K6:O6="לא")*(P6:T6="לא")+0.5*(P6:T6="חלקית")*((K6:O6="כן")+(K6:O6="לא")))/SUMPRODUCT(((K6:O6="כן")+(K6:O6="לא"))*(P6:T6<>"")),"")) | AD6: =IF($A6="","",SUMPRODUCT((K6:O6="כן")*(P6:T6="לא"))) | AE6: =IF($A6="","",SUMPRODUCT((K6:O6="לא")*(P6:T6="כן"))) | AF6: =IF($A6="","",COUNTIF(U6:W6,"כן")) | AG6: =IF($A6="","",IF(AA6<>"מלא",0,IF(OR(AC6="",N(AC6)<0.6),1,IF(AND(AF6>=2,N(X6)>=2),3,2))))
Z7: =IF($A7="","",$A7&"|"&$C7) | AA7: =IF($A7="","",IF(OR(H7="לא נבדק",H7=""),"לא נבדק",IF(AND(H7="בחר/ה בעצמו/ה",I7="כן",J7="לא"),"מלא",IF(OR(H7="בחר/ה בעצמו/ה",I7="כן"),"חלקי","עדיין לא")))) | AB7: =IF($A7="","",COUNTIF(K7:O7,"כן")) | AC7: =IF($A7="","",IFERROR(SUMPRODUCT((K7:O7="כן")*(P7:T7="כן")+(K7:O7="לא")*(P7:T7="לא")+0.5*(P7:T7="חלקית")*((K7:O7="כן")+(K7:O7="לא")))/SUMPRODUCT(((K7:O7="כן")+(K7:O7="לא"))*(P7:T7<>"")),"")) | AD7: =IF($A7="","",SUMPRODUCT((K7:O7="כן")*(P7:T7="לא"))) | AE7: =IF($A7="","",SUMPRODUCT((K7:O7="לא")*(P7:T7="כן"))) | AF7: =IF($A7="","",COUNTIF(U7:W7,"כן")) | AG7: =IF($A7="","",IF(AA7<>"מלא",0,IF(OR(AC7="",N(AC7)<0.6),1,IF(AND(AF7>=2,N(X7)>=2),3,2))))
Z8: =IF($A8="","",$A8&"|"&$C8) | AA8: =IF($A8="","",IF(OR(H8="לא נבדק",H8=""),"לא נבדק",IF(AND(H8="בחר/ה בעצמו/ה",I8="כן",J8="לא"),"מלא",IF(OR(H8="בחר/ה בעצמו/ה",I8="כן"),"חלקי","עדיין לא")))) | AB8: =IF($A8="","",COUNTIF(K8:O8,"כן")) | AC8: =IF($A8="","",IFERROR(SUMPRODUCT((K8:O8="כן")*(P8:T8="כן")+(K8:O8="לא")*(P8:T8="לא")+0.5*(P8:T8="חלקית")*((K8:O8="כן")+(K8:O8="לא")))/SUMPRODUCT(((K8:O8="כן")+(K8:O8="לא"))*(P8:T8<>"")),"")) | AD8: =IF($A8="","",SUMPRODUCT((K8:O8="כן")*(P8:T8="לא"))) | AE8: =IF($A8="","",SUMPRODUCT((K8:O8="לא")*(P8:T8="כן"))) | AF8: =IF($A8="","",COUNTIF(U8:W8,"כן")) | AG8: =IF($A8="","",IF(AA8<>"מלא",0,IF(OR(AC8="",N(AC8)<0.6),1,IF(AND(AF8>=2,N(X8)>=2),3,2))))
Z9: =IF($A9="","",$A9&"|"&$C9) | AA9: =IF($A9="","",IF(OR(H9="לא נבדק",H9=""),"לא נבדק",IF(AND(H9="בחר/ה בעצמו/ה",I9="כן",J9="לא"),"מלא",IF(OR(H9="בחר/ה בעצמו/ה",I9="כן"),"חלקי","עדיין לא")))) | AB9: =IF($A9="","",COUNTIF(K9:O9,"כן")) | AC9: =IF($A9="","",IFERROR(SUMPRODUCT((K9:O9="כן")*(P9:T9="כן")+(K9:O9="לא")*(P9:T9="לא")+0.5*(P9:T9="חלקית")*((K9:O9="כן")+(K9:O9="לא")))/SUMPRODUCT(((K9:O9="כן")+(K9:O9="לא"))*(P9:T9<>"")),"")) | AD9: =IF($A9="","",SUMPRODUCT((K9:O9="כן")*(P9:T9="לא"))) | AE9: =IF($A9="","",SUMPRODUCT((K9:O9="לא")*(P9:T9="כן"))) | AF9: =IF($A9="","",COUNTIF(U9:W9,"כן")) | AG9: =IF($A9="","",IF(AA9<>"מלא",0,IF(OR(AC9="",N(AC9)<0.6),1,IF(AND(AF9>=2,N(X9)>=2),3,2))))
Z10: =IF($A10="","",$A10&"|"&$C10) | AA10: =IF($A10="","",IF(OR(H10="לא נבדק",H10=""),"לא נבדק",IF(AND(H10="בחר/ה בעצמו/ה",I10="כן",J10="לא"),"מלא",IF(OR(H10="בחר/ה בעצמו/ה",I10="כן"),"חלקי","עדיין לא")))) | AB10: =IF($A10="","",COUNTIF(K10:O10,"כן")) | AC10: =IF($A10="","",IFERROR(SUMPRODUCT((K10:O10="כן")*(P10:T10="כן")+(K10:O10="לא")*(P10:T10="לא")+0.5*(P10:T10="חלקית")*((K10:O10="כן")+(K10:O10="לא")))/SUMPRODUCT(((K10:O10="כן")+(K10:O10="לא"))*(P10:T10<>"")),"")) | AD10: =IF($A10="","",SUMPRODUCT((K10:O10="כן")*(P10:T10="לא"))) | AE10: =IF($A10="","",SUMPRODUCT((K10:O10="לא")*(P10:T10="כן"))) | AF10: =IF($A10="","",COUNTIF(U10:W10,"כן")) | AG10: =IF($A10="","",IF(AA10<>"מלא",0,IF(OR(AC10="",N(AC10)<0.6),1,IF(AND(AF10>=2,N(X10)>=2),3,2))))
Z11: =IF($A11="","",$A11&"|"&$C11) | AA11: =IF($A11="","",IF(OR(H11="לא נבדק",H11=""),"לא נבדק",IF(AND(H11="בחר/ה בעצמו/ה",I11="כן",J11="לא"),"מלא",IF(OR(H11="בחר/ה בעצמו/ה",I11="כן"),"חלקי","עדיין לא")))) | AB11: =IF($A11="","",COUNTIF(K11:O11,"כן")) | AC11: =IF($A11="","",IFERROR(SUMPRODUCT((K11:O11="כן")*(P11:T11="כן")+(K11:O11="לא")*(P11:T11="לא")+0.5*(P11:T11="חלקית")*((K11:O11="כן")+(K11:O11="לא")))/SUMPRODUCT(((K11:O11="כן")+(K11:O11="לא"))*(P11:T11<>"")),"")) | AD11: =IF($A11="","",SUMPRODUCT((K11:O11="כן")*(P11:T11="לא"))) | AE11: =IF($A11="","",SUMPRODUCT((K11:O11="לא")*(P11:T11="כן"))) | AF11: =IF($A11="","",COUNTIF(U11:W11,"כן")) | AG11: =IF($A11="","",IF(AA11<>"מלא",0,IF(OR(AC11="",N(AC11)<0.6),1,IF(AND(AF11>=2,N(X11)>=2),3,2))))
Z12: =IF($A12="","",$A12&"|"&$C12) | AA12: =IF($A12="","",IF(OR(H12="לא נבדק",H12=""),"לא נבדק",IF(AND(H12="בחר/ה בעצמו/ה",I12="כן",J12="לא"),"מלא",IF(OR(H12="בחר/ה בעצמו/ה",I12="כן"),"חלקי","עדיין לא")))) | AB12: =IF($A12="","",COUNTIF(K12:O12,"כן")) | AC12: =IF($A12="","",IFERROR(SUMPRODUCT((K12:O12="כן")*(P12:T12="כן")+(K12:O12="לא")*(P12:T12="לא")+0.5*(P12:T12="חלקית")*((K12:O12="כן")+(K12:O12="לא")))/SUMPRODUCT(((K12:O12="כן")+(K12:O12="לא"))*(P12:T12<>"")),"")) | AD12: =IF($A12="","",SUMPRODUCT((K12:O12="כן")*(P12:T12="לא"))) | AE12: =IF($A12="","",SUMPRODUCT((K12:O12="לא")*(P12:T12="כן"))) | AF12: =IF($A12="","",COUNTIF(U12:W12,"כן")) | AG12: =IF($A12="","",IF(AA12<>"מלא",0,IF(OR(AC12="",N(AC12)<0.6),1,IF(AND(AF12>=2,N(X12)>=2),3,2))))
Z13: =IF($A13="","",$A13&"|"&$C13) | AA13: =IF($A13="","",IF(OR(H13="לא נבדק",H13=""),"לא נבדק",IF(AND(H13="בחר/ה בעצמו/ה",I13="כן",J13="לא"),"מלא",IF(OR(H13="בחר/ה בעצמו/ה",I13="כן"),"חלקי","עדיין לא")))) | AB13: =IF($A13="","",COUNTIF(K13:O13,"כן")) | AC13: =IF($A13="","",IFERROR(SUMPRODUCT((K13:O13="כן")*(P13:T13="כן")+(K13:O13="לא")*(P13:T13="לא")+0.5*(P13:T13="חלקית")*((K13:O13="כן")+(K13:O13="לא")))/SUMPRODUCT(((K13:O13="כן")+(K13:O13="לא"))*(P13:T13<>"")),"")) | AD13: =IF($A13="","",SUMPRODUCT((K13:O13="כן")*(P13:T13="לא"))) | AE13: =IF($A13="","",SUMPRODUCT((K13:O13="לא")*(P13:T13="כן"))) | AF13: =IF($A13="","",COUNTIF(U13:W13,"כן")) | AG13: =IF($A13="","",IF(AA13<>"מלא",0,IF(OR(AC13="",N(AC13)<0.6),1,IF(AND(AF13>=2,N(X13)>=2),3,2))))
Z14: =IF($A14="","",$A14&"|"&$C14) | AA14: =IF($A14="","",IF(OR(H14="לא נבדק",H14=""),"לא נבדק",IF(AND(H14="בחר/ה בעצמו/ה",I14="כן",J14="לא"),"מלא",IF(OR(H14="בחר/ה בעצמו/ה",I14="כן"),"חלקי","עדיין לא")))) | AB14: =IF($A14="","",COUNTIF(K14:O14,"כן")) | AC14: =IF($A14="","",IFERROR(SUMPRODUCT((K14:O14="כן")*(P14:T14="כן")+(K14:O14="לא")*(P14:T14="לא")+0.5*(P14:T14="חלקית")*((K14:O14="כן")+(K14:O14="לא")))/SUMPRODUCT(((K14:O14="כן")+(K14:O14="לא"))*(P14:T14<>"")),"")) | AD14: =IF($A14="","",SUMPRODUCT((K14:O14="כן")*(P14:T14="לא"))) | AE14: =IF($A14="","",SUMPRODUCT((K14:O14="לא")*(P14:T14="כן"))) | AF14: =IF($A14="","",COUNTIF(U14:W14,"כן")) | AG14: =IF($A14="","",IF(AA14<>"מלא",0,IF(OR(AC14="",N(AC14)<0.6),1,IF(AND(AF14>=2,N(X14)>=2),3,2))))
Z15: =IF($A15="","",$A15&"|"&$C15) | AA15: =IF($A15="","",IF(OR(H15="לא נבדק",H15=""),"לא נבדק",IF(AND(H15="בחר/ה בעצמו/ה",I15="כן",J15="לא"),"מלא",IF(OR(H15="בחר/ה בעצמו/ה",I15="כן"),"חלקי","עדיין לא")))) | AB15: =IF($A15="","",COUNTIF(K15:O15,"כן")) | AC15: =IF($A15="","",IFERROR(SUMPRODUCT((K15:O15="כן")*(P15:T15="כן")+(K15:O15="לא")*(P15:T15="לא")+0.5*(P15:T15="חלקית")*((K15:O15="כן")+(K15:O15="לא")))/SUMPRODUCT(((K15:O15="כן")+(K15:O15="לא"))*(P15:T15<>"")),"")) | AD15: =IF($A15="","",SUMPRODUCT((K15:O15="כן")*(P15:T15="לא"))) | AE15: =IF($A15="","",SUMPRODUCT((K15:O15="לא")*(P15:T15="כן"))) | AF15: =IF($A15="","",COUNTIF(U15:W15,"כן")) | AG15: =IF($A15="","",IF(AA15<>"מלא",0,IF(OR(AC15="",N(AC15)<0.6),1,IF(AND(AF15>=2,N(X15)>=2),3,2))))
Z16: =IF($A16="","",$A16&"|"&$C16) | AA16: =IF($A16="","",IF(OR(H16="לא נבדק",H16=""),"לא נבדק",IF(AND(H16="בחר/ה בעצמו/ה",I16="כן",J16="לא"),"מלא",IF(OR(H16="בחר/ה בעצמו/ה",I16="כן"),"חלקי","עדיין לא")))) | AB16: =IF($A16="","",COUNTIF(K16:O16,"כן")) | AC16: =IF($A16="","",IFERROR(SUMPRODUCT((K16:O16="כן")*(P16:T16="כן")+(K16:O16="לא")*(P16:T16="לא")+0.5*(P16:T16="חלקית")*((K16:O16="כן")+(K16:O16="לא")))/SUMPRODUCT(((K16:O16="כן")+(K16:O16="לא"))*(P16:T16<>"")),"")) | AD16: =IF($A16="","",SUMPRODUCT((K16:O16="כן")*(P16:T16="לא"))) | AE16: =IF($A16="","",SUMPRODUCT((K16:O16="לא")*(P16:T16="כן"))) | AF16: =IF($A16="","",COUNTIF(U16:W16,"כן")) | AG16: =IF($A16="","",IF(AA16<>"מלא",0,IF(OR(AC16="",N(AC16)<0.6),1,IF(AND(AF16>=2,N(X16)>=2),3,2))))
Z17: =IF($A17="","",$A17&"|"&$C17) | AA17: =IF($A17="","",IF(OR(H17="לא נבדק",H17=""),"לא נבדק",IF(AND(H17="בחר/ה בעצמו/ה",I17="כן",J17="לא"),"מלא",IF(OR(H17="בחר/ה בעצמו/ה",I17="כן"),"חלקי","עדיין לא")))) | AB17: =IF($A17="","",COUNTIF(K17:O17,"כן")) | AC17: =IF($A17="","",IFERROR(SUMPRODUCT((K17:O17="כן")*(P17:T17="כן")+(K17:O17="לא")*(P17:T17="לא")+0.5*(P17:T17="חלקית")*((K17:O17="כן")+(K17:O17="לא")))/SUMPRODUCT(((K17:O17="כן")+(K17:O17="לא"))*(P17:T17<>"")),"")) | AD17: =IF($A17="","",SUMPRODUCT((K17:O17="כן")*(P17:T17="לא"))) | AE17: =IF($A17="","",SUMPRODUCT((K17:O17="לא")*(P17:T17="כן"))) | AF17: =IF($A17="","",COUNTIF(U17:W17,"כן")) | AG17: =IF($A17="","",IF(AA17<>"מלא",0,IF(OR(AC17="",N(AC17)<0.6),1,IF(AND(AF17>=2,N(X17)>=2),3,2))))
... Z204: =IF($A204="","",$A204&"|"&$C204) | AA204: =IF($A204="","",IF(OR(H204="לא נבדק",H204=""),"לא נבדק",IF(AND(H204="בחר/ה בעצמו/ה",I204="כן",J204="לא"),"מלא",IF(OR(H204="בחר/ה בעצמו/ה",I204="כן"),"חלקי","עדיין לא")))) | AB204: =IF($A204="","",COUNTIF(K204:O204,"כן")) | AC204: =IF($A204="","",IFERROR(SUMPRODUCT((K204:O204="כן")*(P204:T204="כן")+(K204:O204="לא")*(P204:T204="לא")+0.5*(P204:T204="חלקית")*((K204:O204="כן")+(K204:O204="לא")))/SUMPRODUCT(((K204:O204="כן")+(K204:O204="לא"))*(P204:T204<>"")),"")) | AD204: =IF($A204="","",SUMPRODUCT((K204:O204="כן")*(P204:T204="לא"))) | AE204: =IF($A204="","",SUMPRODUCT((K204:O204="לא")*(P204:T204="כן"))) | AF204: =IF($A204="","",COUNTIF(U204:W204,"כן")) | AG204: =IF($A204="","",IF(AA204<>"מלא",0,IF(OR(AC204="",N(AC204)<0.6),1,IF(AND(AF204>=2,N(X204)>=2),3,2))))

Sheet רווחה - מעקב
A1: רווחה והשתתפות – מעקב לאורך השנה
A2: כותבים שם תלמיד/ה בעמודה הצהובה, בדיוק כמו בגיליון הקליטה. השאר מתמלא לבד. השינוי מחושב על מדד התצפית.
B3: תחילת שנה | E3: אמצע שנה | H3: סוף שנה | K3: שינוי לאורך השנה
A4: שם התלמיד/ה | B4: מדד תצפית (1–3) | C4: תלמיד/ה – ״כן״ | D4: אמינות | E4: מדד תצפית (1–3) | F4: תלמיד/ה – ״כן״ | G4: אמינות | H4: מדד תצפית (1–3) | I4: תלמיד/ה – ״כן״ | J4: אמינות | K4: שינוי: סוף מול תחילת שנה | L4: מגמה
A5: תלמיד לדוגמה | B5: =IF($A5="","",IFERROR(AVERAGEIFS('רווחה - קליטה'!$AQ$5:$AQ$204,'רווחה - קליטה'!$A$5:$A$204,$A5,'רווחה - קליטה'!$C$5:$C$204,"תחילת שנה"),"")) -> 2.1111111 | C5: =IF($A5="","",IFERROR(AVERAGEIFS('רווחה - קליטה'!$AK$5:$AK$204,'רווחה - קליטה'!$A$5:$A$204,$A5,'רווחה - קליטה'!$C$5:$C$204,"תחילת שנה"),"")) -> 0.75 | D5: =IF($A5="","",IFERROR(INDEX('רווחה - קליטה'!$AS$5:$AS$204,MATCH($A5&"|תחילת שנה",'רווחה - קליטה'!$AE$5:$AE$204,0)),"")) -> אמין | E5: =IF($A5="","",IFERROR(AVERAGEIFS('רווחה - קליטה'!$AQ$5:$AQ$204,'רווחה - קליטה'!$A$5:$A$204,$A5,'רווחה - קליטה'!$C$5:$C$204,"אמצע שנה"),"")) | F5: =IF($A5="","",IFERROR(AVERAGEIFS('רווחה - קליטה'!$AK$5:$AK$204,'רווחה - קליטה'!$A$5:$A$204,$A5,'רווחה - קליטה'!$C$5:$C$204,"אמצע שנה"),"")) | G5: =IF($A5="","",IFERROR(INDEX('רווחה - קליטה'!$AS$5:$AS$204,MATCH($A5&"|אמצע שנה",'רווחה - קליטה'!$AE$5:$AE$204,0)),"")) | H5: =IF($A5="","",IFERROR(AVERAGEIFS('רווחה - קליטה'!$AQ$5:$AQ$204,'רווחה - קליטה'!$A$5:$A$204,$A5,'רווחה - קליטה'!$C$5:$C$204,"סוף שנה"),"")) | I5: =IF($A5="","",IFERROR(AVERAGEIFS('רווחה - קליטה'!$AK$5:$AK$204,'רווחה - קליטה'!$A$5:$A$204,$A5,'רווחה - קליטה'!$C$5:$C$204,"סוף שנה"),"")) | J5: =IF($A5="","",IFERROR(INDEX('רווחה - קליטה'!$AS$5:$AS$204,MATCH($A5&"|סוף שנה",'רווחה - קליטה'!$AE$5:$AE$204,0)),"")) | K5: =IF(AND(ISNUMBER(B5),ISNUMBER(H5)),H5-B5,"") | L5: =IF(K5="","",IF(K5>=0.5,"עלייה",IF(K5<=-0.5,"ירידה","יציב")))
B6: =IF($A6="","",IFERROR(AVERAGEIFS('רווחה - קליטה'!$AQ$5:$AQ$204,'רווחה - קליטה'!$A$5:$A$204,$A6,'רווחה - קליטה'!$C$5:$C$204,"תחילת שנה"),"")) | C6: =IF($A6="","",IFERROR(AVERAGEIFS('רווחה - קליטה'!$AK$5:$AK$204,'רווחה - קליטה'!$A$5:$A$204,$A6,'רווחה - קליטה'!$C$5:$C$204,"תחילת שנה"),"")) | D6: =IF($A6="","",IFERROR(INDEX('רווחה - קליטה'!$AS$5:$AS$204,MATCH($A6&"|תחילת שנה",'רווחה - קליטה'!$AE$5:$AE$204,0)),"")) | E6: =IF($A6="","",IFERROR(AVERAGEIFS('רווחה - קליטה'!$AQ$5:$AQ$204,'רווחה - קליטה'!$A$5:$A$204,$A6,'רווחה - קליטה'!$C$5:$C$204,"אמצע שנה"),"")) | F6: =IF($A6="","",IFERROR(AVERAGEIFS('רווחה - קליטה'!$AK$5:$AK$204,'רווחה - קליטה'!$A$5:$A$204,$A6,'רווחה - קליטה'!$C$5:$C$204,"אמצע שנה"),"")) | G6: =IF($A6="","",IFERROR(INDEX('רווחה - קליטה'!$AS$5:$AS$204,MATCH($A6&"|אמצע שנה",'רווחה - קליטה'!$AE$5:$AE$204,0)),"")) | H6: =IF($A6="","",IFERROR(AVERAGEIFS('רווחה - קליטה'!$AQ$5:$AQ$204,'רווחה - קליטה'!$A$5:$A$204,$A6,'רווחה - קליטה'!$C$5:$C$204,"סוף שנה"),"")) | I6: =IF($A6="","",IFERROR(AVERAGEIFS('רווחה - קליטה'!$AK$5:$AK$204,'רווחה - קליטה'!$A$5:$A$204,$A6,'רווחה - קליטה'!$C$5:$C$204,"סוף שנה"),"")) | J6: =IF($A6="","",IFERROR(INDEX('רווחה - קליטה'!$AS$5:$AS$204,MATCH($A6&"|סוף שנה",'רווחה - קליטה'!$AE$5:$AE$204,0)),"")) | K6: =IF(AND(ISNUMBER(B6),ISNUMBER(H6)),H6-B6,"") | L6: =IF(K6="","",IF(K6>=0.5,"עלייה",IF(K6<=-0.5,"ירידה","יציב")))
B7: =IF($A7="","",IFERROR(AVERAGEIFS('רווחה - קליטה'!$AQ$5:$AQ$204,'רווחה - קליטה'!$A$5:$A$204,$A7,'רווחה - קליטה'!$C$5:$C$204,"תחילת שנה"),"")) | C7: =IF($A7="","",IFERROR(AVERAGEIFS('רווחה - קליטה'!$AK$5:$AK$204,'רווחה - קליטה'!$A$5:$A$204,$A7,'רווחה - קליטה'!$C$5:$C$204,"תחילת שנה"),"")) | D7: =IF($A7="","",IFERROR(INDEX('רווחה - קליטה'!$AS$5:$AS$204,MATCH($A7&"|תחילת שנה",'רווחה - קליטה'!$AE$5:$AE$204,0)),"")) | E7: =IF($A7="","",IFERROR(AVERAGEIFS('רווחה - קליטה'!$AQ$5:$AQ$204,'רווחה - קליטה'!$A$5:$A$204,$A7,'רווחה - קליטה'!$C$5:$C$204,"אמצע שנה"),"")) | F7: =IF($A7="","",IFERROR(AVERAGEIFS('רווחה - קליטה'!$AK$5:$AK$204,'רווחה - קליטה'!$A$5:$A$204,$A7,'רווחה - קליטה'!$C$5:$C$204,"אמצע שנה"),"")) | G7: =IF($A7="","",IFERROR(INDEX('רווחה - קליטה'!$AS$5:$AS$204,MATCH($A7&"|אמצע שנה",'רווחה - קליטה'!$AE$5:$AE$204,0)),"")) | H7: =IF($A7="","",IFERROR(AVERAGEIFS('רווחה - קליטה'!$AQ$5:$AQ$204,'רווחה - קליטה'!$A$5:$A$204,$A7,'רווחה - קליטה'!$C$5:$C$204,"סוף שנה"),"")) | I7: =IF($A7="","",IFERROR(AVERAGEIFS('רווחה - קליטה'!$AK$5:$AK$204,'רווחה - קליטה'!$A$5:$A$204,$A7,'רווחה - קליטה'!$C$5:$C$204,"סוף שנה"),"")) | J7: =IF($A7="","",IFERROR(INDEX('רווחה - קליטה'!$AS$5:$AS$204,MATCH($A7&"|סוף שנה",'רווחה - קליטה'!$AE$5:$AE$204,0)),"")) | K7: =IF(AND(ISNUMBER(B7),ISNUMBER(H7)),H7-B7,"") | L7: =IF(K7="","",IF(K7>=0.5,"עלייה",IF(K7<=-0.5,"ירידה","יציב")))
B8: =IF($A8="","",IFERROR(AVERAGEIFS('רווחה - קליטה'!$AQ$5:$AQ$204,'רווחה - קליטה'!$A$5:$A$204,$A8,'רווחה - קליטה'!$C$5:$C$204,"תחילת שנה"),"")) | C8: =IF($A8="","",IFERROR(AVERAGEIFS('רווחה - קליטה'!$AK$5:$AK$204,'רווחה - קליטה'!$A$5:$A$204,$A8,'רווחה - קליטה'!$C$5:$C$204,"תחילת שנה"),"")) | D8: =IF($A8="","",IFERROR(INDEX('רווחה - קליטה'!$AS$5:$AS$204,MATCH($A8&"|תחילת שנה",'רווחה - קליטה'!$AE$5:$AE$204,0)),"")) | E8: =IF($A8="","",IFERROR(AVERAGEIFS('רווחה - קליטה'!$AQ$5:$AQ$204,'רווחה - קליטה'!$A$5:$A$204,$A8,'רווחה - קליטה'!$C$5:$C$204,"אמצע שנה"),"")) | F8: =IF($A8="","",IFERROR(AVERAGEIFS('רווחה - קליטה'!$AK$5:$AK$204,'רווחה - קליטה'!$A$5:$A$204,$A8,'רווחה - קליטה'!$C$5:$C$204,"אמצע שנה"),"")) | G8: =IF($A8="","",IFERROR(INDEX('רווחה - קליטה'!$AS$5:$AS$204,MATCH($A8&"|אמצע שנה",'רווחה - קליטה'!$AE$5:$AE$204,0)),"")) | H8: =IF($A8="","",IFERROR(AVERAGEIFS('רווחה - קליטה'!$AQ$5:$AQ$204,'רווחה - קליטה'!$A$5:$A$204,$A8,'רווחה - קליטה'!$C$5:$C$204,"סוף שנה"),"")) | I8: =IF($A8="","",IFERROR(AVERAGEIFS('רווחה - קליטה'!$AK$5:$AK$204,'רווחה - קליטה'!$A$5:$A$204,$A8,'רווחה - קליטה'!$C$5:$C$204,"סוף שנה"),"")) | J8: =IF($A8="","",IFERROR(INDEX('רווחה - קליטה'!$AS$5:$AS$204,MATCH($A8&"|סוף שנה",'רווחה - קליטה'!$AE$5:$AE$204,0)),"")) | K8: =IF(AND(ISNUMBER(B8),ISNUMBER(H8)),H8-B8,"") | L8: =IF(K8="","",IF(K8>=0.5,"עלייה",IF(K8<=-0.5,"ירידה","יציב")))
B9: =IF($A9="","",IFERROR(AVERAGEIFS('רווחה - קליטה'!$AQ$5:$AQ$204,'רווחה - קליטה'!$A$5:$A$204,$A9,'רווחה - קליטה'!$C$5:$C$204,"תחילת שנה"),"")) | C9: =IF($A9="","",IFERROR(AVERAGEIFS('רווחה - קליטה'!$AK$5:$AK$204,'רווחה - קליטה'!$A$5:$A$204,$A9,'רווחה - קליטה'!$C$5:$C$204,"תחילת שנה"),"")) | D9: =IF($A9="","",IFERROR(INDEX('רווחה - קליטה'!$AS$5:$AS$204,MATCH($A9&"|תחילת שנה",'רווחה - קליטה'!$AE$5:$AE$204,0)),"")) | E9: =IF($A9="","",IFERROR(AVERAGEIFS('רווחה - קליטה'!$AQ$5:$AQ$204,'רווחה - קליטה'!$A$5:$A$204,$A9,'רווחה - קליטה'!$C$5:$C$204,"אמצע שנה"),"")) | F9: =IF($A9="","",IFERROR(AVERAGEIFS('רווחה - קליטה'!$AK$5:$AK$204,'רווחה - קליטה'!$A$5:$A$204,$A9,'רווחה - קליטה'!$C$5:$C$204,"אמצע שנה"),"")) | G9: =IF($A9="","",IFERROR(INDEX('רווחה - קליטה'!$AS$5:$AS$204,MATCH($A9&"|אמצע שנה",'רווחה - קליטה'!$AE$5:$AE$204,0)),"")) | H9: =IF($A9="","",IFERROR(AVERAGEIFS('רווחה - קליטה'!$AQ$5:$AQ$204,'רווחה - קליטה'!$A$5:$A$204,$A9,'רווחה - קליטה'!$C$5:$C$204,"סוף שנה"),"")) | I9: =IF($A9="","",IFERROR(AVERAGEIFS('רווחה - קליטה'!$AK$5:$AK$204,'רווחה - קליטה'!$A$5:$A$204,$A9,'רווחה - קליטה'!$C$5:$C$204,"סוף שנה"),"")) | J9: =IF($A9="","",IFERROR(INDEX('רווחה - קליטה'!$AS$5:$AS$204,MATCH($A9&"|סוף שנה",'רווחה - קליטה'!$AE$5:$AE$204,0)),"")) | K9: =IF(AND(ISNUMBER(B9),ISNUMBER(H9)),H9-B9,"") | L9: =IF(K9="","",IF(K9>=0.5,"עלייה",IF(K9<=-0.5,"ירידה","יציב")))
B10: =IF($A10="","",IFERROR(AVERAGEIFS('רווחה - קליטה'!$AQ$5:$AQ$204,'רווחה - קליטה'!$A$5:$A$204,$A10,'רווחה - קליטה'!$C$5:$C$204,"תחילת שנה"),"")) | C10: =IF($A10="","",IFERROR(AVERAGEIFS('רווחה - קליטה'!$AK$5:$AK$204,'רווחה - קליטה'!$A$5:$A$204,$A10,'רווחה - קליטה'!$C$5:$C$204,"תחילת שנה"),"")) | D10: =IF($A10="","",IFERROR(INDEX('רווחה - קליטה'!$AS$5:$AS$204,MATCH($A10&"|תחילת שנה",'רווחה - קליטה'!$AE$5:$AE$204,0)),"")) | E10: =IF($A10="","",IFERROR(AVERAGEIFS('רווחה - קליטה'!$AQ$5:$AQ$204,'רווחה - קליטה'!$A$5:$A$204,$A10,'רווחה - קליטה'!$C$5:$C$204,"אמצע שנה"),"")) | F10: =IF($A10="","",IFERROR(AVERAGEIFS('רווחה - קליטה'!$AK$5:$AK$204,'רווחה - קליטה'!$A$5:$A$204,$A10,'רווחה - קליטה'!$C$5:$C$204,"אמצע שנה"),"")) | G10: =IF($A10="","",IFERROR(INDEX('רווחה - קליטה'!$AS$5:$AS$204,MATCH($A10&"|אמצע שנה",'רווחה - קליטה'!$AE$5:$AE$204,0)),"")) | H10: =IF($A10="","",IFERROR(AVERAGEIFS('רווחה - קליטה'!$AQ$5:$AQ$204,'רווחה - קליטה'!$A$5:$A$204,$A10,'רווחה - קליטה'!$C$5:$C$204,"סוף שנה"),"")) | I10: =IF($A10="","",IFERROR(AVERAGEIFS('רווחה - קליטה'!$AK$5:$AK$204,'רווחה - קליטה'!$A$5:$A$204,$A10,'רווחה - קליטה'!$C$5:$C$204,"סוף שנה"),"")) | J10: =IF($A10="","",IFERROR(INDEX('רווחה - קליטה'!$AS$5:$AS$204,MATCH($A10&"|סוף שנה",'רווחה - קליטה'!$AE$5:$AE$204,0)),"")) | K10: =IF(AND(ISNUMBER(B10),ISNUMBER(H10)),H10-B10,"") | L10: =IF(K10="","",IF(K10>=0.5,"עלייה",IF(K10<=-0.5,"ירידה","יציב")))
B11: =IF($A11="","",IFERROR(AVERAGEIFS('רווחה - קליטה'!$AQ$5:$AQ$204,'רווחה - קליטה'!$A$5:$A$204,$A11,'רווחה - קליטה'!$C$5:$C$204,"תחילת שנה"),"")) | C11: =IF($A11="","",IFERROR(AVERAGEIFS('רווחה - קליטה'!$AK$5:$AK$204,'רווחה - קליטה'!$A$5:$A$204,$A11,'רווחה - קליטה'!$C$5:$C$204,"תחילת שנה"),"")) | D11: =IF($A11="","",IFERROR(INDEX('רווחה - קליטה'!$AS$5:$AS$204,MATCH($A11&"|תחילת שנה",'רווחה - קליטה'!$AE$5:$AE$204,0)),"")) | E11: =IF($A11="","",IFERROR(AVERAGEIFS('רווחה - קליטה'!$AQ$5:$AQ$204,'רווחה - קליטה'!$A$5:$A$204,$A11,'רווחה - קליטה'!$C$5:$C$204,"אמצע שנה"),"")) | F11: =IF($A11="","",IFERROR(AVERAGEIFS('רווחה - קליטה'!$AK$5:$AK$204,'רווחה - קליטה'!$A$5:$A$204,$A11,'רווחה - קליטה'!$C$5:$C$204,"אמצע שנה"),"")) | G11: =IF($A11="","",IFERROR(INDEX('רווחה - קליטה'!$AS$5:$AS$204,MATCH($A11&"|אמצע שנה",'רווחה - קליטה'!$AE$5:$AE$204,0)),"")) | H11: =IF($A11="","",IFERROR(AVERAGEIFS('רווחה - קליטה'!$AQ$5:$AQ$204,'רווחה - קליטה'!$A$5:$A$204,$A11,'רווחה - קליטה'!$C$5:$C$204,"סוף שנה"),"")) | I11: =IF($A11="","",IFERROR(AVERAGEIFS('רווחה - קליטה'!$AK$5:$AK$204,'רווחה - קליטה'!$A$5:$A$204,$A11,'רווחה - קליטה'!$C$5:$C$204,"סוף שנה"),"")) | J11: =IF($A11="","",IFERROR(INDEX('רווחה - קליטה'!$AS$5:$AS$204,MATCH($A11&"|סוף שנה",'רווחה - קליטה'!$AE$5:$AE$204,0)),"")) | K11: =IF(AND(ISNUMBER(B11),ISNUMBER(H11)),H11-B11,"") | L11: =IF(K11="","",IF(K11>=0.5,"עלייה",IF(K11<=-0.5,"ירידה","יציב")))
B12: =IF($A12="","",IFERROR(AVERAGEIFS('רווחה - קליטה'!$AQ$5:$AQ$204,'רווחה - קליטה'!$A$5:$A$204,$A12,'רווחה - קליטה'!$C$5:$C$204,"תחילת שנה"),"")) | C12: =IF($A12="","",IFERROR(AVERAGEIFS('רווחה - קליטה'!$AK$5:$AK$204,'רווחה - קליטה'!$A$5:$A$204,$A12,'רווחה - קליטה'!$C$5:$C$204,"תחילת שנה"),"")) | D12: =IF($A12="","",IFERROR(INDEX('רווחה - קליטה'!$AS$5:$AS$204,MATCH($A12&"|תחילת שנה",'רווחה - קליטה'!$AE$5:$AE$204,0)),"")) | E12: =IF($A12="","",IFERROR(AVERAGEIFS('רווחה - קליטה'!$AQ$5:$AQ$204,'רווחה - קליטה'!$A$5:$A$204,$A12,'רווחה - קליטה'!$C$5:$C$204,"אמצע שנה"),"")) | F12: =IF($A12="","",IFERROR(AVERAGEIFS('רווחה - קליטה'!$AK$5:$AK$204,'רווחה - קליטה'!$A$5:$A$204,$A12,'רווחה - קליטה'!$C$5:$C$204,"אמצע שנה"),"")) | G12: =IF($A12="","",IFERROR(INDEX('רווחה - קליטה'!$AS$5:$AS$204,MATCH($A12&"|אמצע שנה",'רווחה - קליטה'!$AE$5:$AE$204,0)),"")) | H12: =IF($A12="","",IFERROR(AVERAGEIFS('רווחה - קליטה'!$AQ$5:$AQ$204,'רווחה - קליטה'!$A$5:$A$204,$A12,'רווחה - קליטה'!$C$5:$C$204,"סוף שנה"),"")) | I12: =IF($A12="","",IFERROR(AVERAGEIFS('רווחה - קליטה'!$AK$5:$AK$204,'רווחה - קליטה'!$A$5:$A$204,$A12,'רווחה - קליטה'!$C$5:$C$204,"סוף שנה"),"")) | J12: =IF($A12="","",IFERROR(INDEX('רווחה - קליטה'!$AS$5:$AS$204,MATCH($A12&"|סוף שנה",'רווחה - קליטה'!$AE$5:$AE$204,0)),"")) | K12: =IF(AND(ISNUMBER(B12),ISNUMBER(H12)),H12-B12,"") | L12: =IF(K12="","",IF(K12>=0.5,"עלייה",IF(K12<=-0.5,"ירידה","יציב")))
B13: =IF($A13="","",IFERROR(AVERAGEIFS('רווחה - קליטה'!$AQ$5:$AQ$204,'רווחה - קליטה'!$A$5:$A$204,$A13,'רווחה - קליטה'!$C$5:$C$204,"תחילת שנה"),"")) | C13: =IF($A13="","",IFERROR(AVERAGEIFS('רווחה - קליטה'!$AK$5:$AK$204,'רווחה - קליטה'!$A$5:$A$204,$A13,'רווחה - קליטה'!$C$5:$C$204,"תחילת שנה"),"")) | D13: =IF($A13="","",IFERROR(INDEX('רווחה - קליטה'!$AS$5:$AS$204,MATCH($A13&"|תחילת שנה",'רווחה - קליטה'!$AE$5:$AE$204,0)),"")) | E13: =IF($A13="","",IFERROR(AVERAGEIFS('רווחה - קליטה'!$AQ$5:$AQ$204,'רווחה - קליטה'!$A$5:$A$204,$A13,'רווחה - קליטה'!$C$5:$C$204,"אמצע שנה"),"")) | F13: =IF($A13="","",IFERROR(AVERAGEIFS('רווחה - קליטה'!$AK$5:$AK$204,'רווחה - קליטה'!$A$5:$A$204,$A13,'רווחה - קליטה'!$C$5:$C$204,"אמצע שנה"),"")) | G13: =IF($A13="","",IFERROR(INDEX('רווחה - קליטה'!$AS$5:$AS$204,MATCH($A13&"|אמצע שנה",'רווחה - קליטה'!$AE$5:$AE$204,0)),"")) | H13: =IF($A13="","",IFERROR(AVERAGEIFS('רווחה - קליטה'!$AQ$5:$AQ$204,'רווחה - קליטה'!$A$5:$A$204,$A13,'רווחה - קליטה'!$C$5:$C$204,"סוף שנה"),"")) | I13: =IF($A13="","",IFERROR(AVERAGEIFS('רווחה - קליטה'!$AK$5:$AK$204,'רווחה - קליטה'!$A$5:$A$204,$A13,'רווחה - קליטה'!$C$5:$C$204,"סוף שנה"),"")) | J13: =IF($A13="","",IFERROR(INDEX('רווחה - קליטה'!$AS$5:$AS$204,MATCH($A13&"|סוף שנה",'רווחה - קליטה'!$AE$5:$AE$204,0)),"")) | K13: =IF(AND(ISNUMBER(B13),ISNUMBER(H13)),H13-B13,"") | L13: =IF(K13="","",IF(K13>=0.5,"עלייה",IF(K13<=-0.5,"ירידה","יציב")))
B14: =IF($A14="","",IFERROR(AVERAGEIFS('רווחה - קליטה'!$AQ$5:$AQ$204,'רווחה - קליטה'!$A$5:$A$204,$A14,'רווחה - קליטה'!$C$5:$C$204,"תחילת שנה"),"")) | C14: =IF($A14="","",IFERROR(AVERAGEIFS('רווחה - קליטה'!$AK$5:$AK$204,'רווחה - קליטה'!$A$5:$A$204,$A14,'רווחה - קליטה'!$C$5:$C$204,"תחילת שנה"),"")) | D14: =IF($A14="","",IFERROR(INDEX('רווחה - קליטה'!$AS$5:$AS$204,MATCH($A14&"|תחילת שנה",'רווחה - קליטה'!$AE$5:$AE$204,0)),"")) | E14: =IF($A14="","",IFERROR(AVERAGEIFS('רווחה - קליטה'!$AQ$5:$AQ$204,'רווחה - קליטה'!$A$5:$A$204,$A14,'רווחה - קליטה'!$C$5:$C$204,"אמצע שנה"),"")) | F14: =IF($A14="","",IFERROR(AVERAGEIFS('רווחה - קליטה'!$AK$5:$AK$204,'רווחה - קליטה'!$A$5:$A$204,$A14,'רווחה - קליטה'!$C$5:$C$204,"אמצע שנה"),"")) | G14: =IF($A14="","",IFERROR(INDEX('רווחה - קליטה'!$AS$5:$AS$204,MATCH($A14&"|אמצע שנה",'רווחה - קליטה'!$AE$5:$AE$204,0)),"")) | H14: =IF($A14="","",IFERROR(AVERAGEIFS('רווחה - קליטה'!$AQ$5:$AQ$204,'רווחה - קליטה'!$A$5:$A$204,$A14,'רווחה - קליטה'!$C$5:$C$204,"סוף שנה"),"")) | I14: =IF($A14="","",IFERROR(AVERAGEIFS('רווחה - קליטה'!$AK$5:$AK$204,'רווחה - קליטה'!$A$5:$A$204,$A14,'רווחה - קליטה'!$C$5:$C$204,"סוף שנה"),"")) | J14: =IF($A14="","",IFERROR(INDEX('רווחה - קליטה'!$AS$5:$AS$204,MATCH($A14&"|סוף שנה",'רווחה - קליטה'!$AE$5:$AE$204,0)),"")) | K14: =IF(AND(ISNUMBER(B14),ISNUMBER(H14)),H14-B14,"") | L14: =IF(K14="","",IF(K14>=0.5,"עלייה",IF(K14<=-0.5,"ירידה","יציב")))
B15: =IF($A15="","",IFERROR(AVERAGEIFS('רווחה - קליטה'!$AQ$5:$AQ$204,'רווחה - קליטה'!$A$5:$A$204,$A15,'רווחה - קליטה'!$C$5:$C$204,"תחילת שנה"),"")) | C15: =IF($A15="","",IFERROR(AVERAGEIFS('רווחה - קליטה'!$AK$5:$AK$204,'רווחה - קליטה'!$A$5:$A$204,$A15,'רווחה - קליטה'!$C$5:$C$204,"תחילת שנה"),"")) | D15: =IF($A15="","",IFERROR(INDEX('רווחה - קליטה'!$AS$5:$AS$204,MATCH($A15&"|תחילת שנה",'רווחה - קליטה'!$AE$5:$AE$204,0)),"")) | E15: =IF($A15="","",IFERROR(AVERAGEIFS('רווחה - קליטה'!$AQ$5:$AQ$204,'רווחה - קליטה'!$A$5:$A$204,$A15,'רווחה - קליטה'!$C$5:$C$204,"אמצע שנה"),"")) | F15: =IF($A15="","",IFERROR(AVERAGEIFS('רווחה - קליטה'!$AK$5:$AK$204,'רווחה - קליטה'!$A$5:$A$204,$A15,'רווחה - קליטה'!$C$5:$C$204,"אמצע שנה"),"")) | G15: =IF($A15="","",IFERROR(INDEX('רווחה - קליטה'!$AS$5:$AS$204,MATCH($A15&"|אמצע שנה",'רווחה - קליטה'!$AE$5:$AE$204,0)),"")) | H15: =IF($A15="","",IFERROR(AVERAGEIFS('רווחה - קליטה'!$AQ$5:$AQ$204,'רווחה - קליטה'!$A$5:$A$204,$A15,'רווחה - קליטה'!$C$5:$C$204,"סוף שנה"),"")) | I15: =IF($A15="","",IFERROR(AVERAGEIFS('רווחה - קליטה'!$AK$5:$AK$204,'רווחה - קליטה'!$A$5:$A$204,$A15,'רווחה - קליטה'!$C$5:$C$204,"סוף שנה"),"")) | J15: =IF($A15="","",IFERROR(INDEX('רווחה - קליטה'!$AS$5:$AS$204,MATCH($A15&"|סוף שנה",'רווחה - קליטה'!$AE$5:$AE$204,0)),"")) | K15: =IF(AND(ISNUMBER(B15),ISNUMBER(H15)),H15-B15,"") | L15: =IF(K15="","",IF(K15>=0.5,"עלייה",IF(K15<=-0.5,"ירידה","יציב")))
B16: =IF($A16="","",IFERROR(AVERAGEIFS('רווחה - קליטה'!$AQ$5:$AQ$204,'רווחה - קליטה'!$A$5:$A$204,$A16,'רווחה - קליטה'!$C$5:$C$204,"תחילת שנה"),"")) | C16: =IF($A16="","",IFERROR(AVERAGEIFS('רווחה - קליטה'!$AK$5:$AK$204,'רווחה - קליטה'!$A$5:$A$204,$A16,'רווחה - קליטה'!$C$5:$C$204,"תחילת שנה"),"")) | D16: =IF($A16="","",IFERROR(INDEX('רווחה - קליטה'!$AS$5:$AS$204,MATCH($A16&"|תחילת שנה",'רווחה - קליטה'!$AE$5:$AE$204,0)),"")) | E16: =IF($A16="","",IFERROR(AVERAGEIFS('רווחה - קליטה'!$AQ$5:$AQ$204,'רווחה - קליטה'!$A$5:$A$204,$A16,'רווחה - קליטה'!$C$5:$C$204,"אמצע שנה"),"")) | F16: =IF($A16="","",IFERROR(AVERAGEIFS('רווחה - קליטה'!$AK$5:$AK$204,'רווחה - קליטה'!$A$5:$A$204,$A16,'רווחה - קליטה'!$C$5:$C$204,"אמצע שנה"),"")) | G16: =IF($A16="","",IFERROR(INDEX('רווחה - קליטה'!$AS$5:$AS$204,MATCH($A16&"|אמצע שנה",'רווחה - קליטה'!$AE$5:$AE$204,0)),"")) | H16: =IF($A16="","",IFERROR(AVERAGEIFS('רווחה - קליטה'!$AQ$5:$AQ$204,'רווחה - קליטה'!$A$5:$A$204,$A16,'רווחה - קליטה'!$C$5:$C$204,"סוף שנה"),"")) | I16: =IF($A16="","",IFERROR(AVERAGEIFS('רווחה - קליטה'!$AK$5:$AK$204,'רווחה - קליטה'!$A$5:$A$204,$A16,'רווחה - קליטה'!$C$5:$C$204,"סוף שנה"),"")) | J16: =IF($A16="","",IFERROR(INDEX('רווחה - קליטה'!$AS$5:$AS$204,MATCH($A16&"|סוף שנה",'רווחה - קליטה'!$AE$5:$AE$204,0)),"")) | K16: =IF(AND(ISNUMBER(B16),ISNUMBER(H16)),H16-B16,"") | L16: =IF(K16="","",IF(K16>=0.5,"עלייה",IF(K16<=-0.5,"ירידה","יציב")))
B17: =IF($A17="","",IFERROR(AVERAGEIFS('רווחה - קליטה'!$AQ$5:$AQ$204,'רווחה - קליטה'!$A$5:$A$204,$A17,'רווחה - קליטה'!$C$5:$C$204,"תחילת שנה"),"")) | C17: =IF($A17="","",IFERROR(AVERAGEIFS('רווחה - קליטה'!$AK$5:$AK$204,'רווחה - קליטה'!$A$5:$A$204,$A17,'רווחה - קליטה'!$C$5:$C$204,"תחילת שנה"),"")) | D17: =IF($A17="","",IFERROR(INDEX('רווחה - קליטה'!$AS$5:$AS$204,MATCH($A17&"|תחילת שנה",'רווחה - קליטה'!$AE$5:$AE$204,0)),"")) | E17: =IF($A17="","",IFERROR(AVERAGEIFS('רווחה - קליטה'!$AQ$5:$AQ$204,'רווחה - קליטה'!$A$5:$A$204,$A17,'רווחה - קליטה'!$C$5:$C$204,"אמצע שנה"),"")) | F17: =IF($A17="","",IFERROR(AVERAGEIFS('רווחה - קליטה'!$AK$5:$AK$204,'רווחה - קליטה'!$A$5:$A$204,$A17,'רווחה - קליטה'!$C$5:$C$204,"אמצע שנה"),"")) | G17: =IF($A17="","",IFERROR(INDEX('רווחה - קליטה'!$AS$5:$AS$204,MATCH($A17&"|אמצע שנה",'רווחה - קליטה'!$AE$5:$AE$204,0)),"")) | H17: =IF($A17="","",IFERROR(AVERAGEIFS('רווחה - קליטה'!$AQ$5:$AQ$204,'רווחה - קליטה'!$A$5:$A$204,$A17,'רווחה - קליטה'!$C$5:$C$204,"סוף שנה"),"")) | I17: =IF($A17="","",IFERROR(AVERAGEIFS('רווחה - קליטה'!$AK$5:$AK$204,'רווחה - קליטה'!$A$5:$A$204,$A17,'רווחה - קליטה'!$C$5:$C$204,"סוף שנה"),"")) | J17: =IF($A17="","",IFERROR(INDEX('רווחה - קליטה'!$AS$5:$AS$204,MATCH($A17&"|סוף שנה",'רווחה - קליטה'!$AE$5:$AE$204,0)),"")) | K17: =IF(AND(ISNUMBER(B17),ISNUMBER(H17)),H17-B17,"") | L17: =IF(K17="","",IF(K17>=0.5,"עלייה",IF(K17<=-0.5,"ירידה","יציב")))
... B204: =IF($A204="","",IFERROR(AVERAGEIFS('רווחה - קליטה'!$AQ$5:$AQ$204,'רווחה - קליטה'!$A$5:$A$204,$A204,'רווחה - קליטה'!$C$5:$C$204,"תחילת שנה"),"")) | C204: =IF($A204="","",IFERROR(AVERAGEIFS('רווחה - קליטה'!$AK$5:$AK$204,'רווחה - קליטה'!$A$5:$A$204,$A204,'רווחה - קליטה'!$C$5:$C$204,"תחילת שנה"),"")) | D204: =IF($A204="","",IFERROR(INDEX('רווחה - קליטה'!$AS$5:$AS$204,MATCH($A204&"|תחילת שנה",'רווחה - קליטה'!$AE$5:$AE$204,0)),"")) | E204: =IF($A204="","",IFERROR(AVERAGEIFS('רווחה - קליטה'!$AQ$5:$AQ$204,'רווחה - קליטה'!$A$5:$A$204,$A204,'רווחה - קליטה'!$C$5:$C$204,"אמצע שנה"),"")) | F204: =IF($A204="","",IFERROR(AVERAGEIFS('רווחה - קליטה'!$AK$5:$AK$204,'רווחה - קליטה'!$A$5:$A$204,$A204,'רווחה - קליטה'!$C$5:$C$204,"אמצע שנה"),"")) | G204: =IF($A204="","",IFERROR(INDEX('רווחה - קליטה'!$AS$5:$AS$204,MATCH($A204&"|אמצע שנה",'רווחה - קליטה'!$AE$5:$AE$204,0)),"")) | H204: =IF($A204="","",IFERROR(AVERAGEIFS('רווחה - קליטה'!$AQ$5:$AQ$204,'רווחה - קליטה'!$A$5:$A$204,$A204,'רווחה - קליטה'!$C$5:$C$204,"סוף שנה"),"")) | I204: =IF($A204="","",IFERROR(AVERAGEIFS('רווחה - קליטה'!$AK$5:$AK$204,'רווחה - קליטה'!$A$5:$A$204,$A204,'רווחה - קליטה'!$C$5:$C$204,"סוף שנה"),"")) | J204: =IF($A204="","",IFERROR(INDEX('רווחה - קליטה'!$AS$5:$AS$204,MATCH($A204&"|סוף שנה",'רווחה - קליטה'!$AE$5:$AE$204,0)),"")) | K204: =IF(AND(ISNUMBER(B204),ISNUMBER(H204)),H204-B204,"") | L204: =IF(K204="","",IF(K204>=0.5,"עלייה",IF(K204<=-0.5,"ירידה","יציב")))

Sheet זה אני - מעקב
A1: ״זה אני״ – מעקב לאורך השנה
A2: כותבים שם תלמיד/ה בעמודה הצהובה, בדיוק כמו בגיליון הקליטה. השינוי מחושב על הרמה שהושגה (0–3).
B3: תחילת שנה | E3: אמצע שנה | H3: סוף שנה | K3: שינוי לאורך השנה
A4: שם התלמיד/ה | B4: רמה (0–3) | C4: זיהוי עצמי | D4: דיוק ״אני יכול/ה״ | E4: רמה (0–3) | F4: זיהוי עצמי | G4: דיוק ״אני יכול/ה״ | H4: רמה (0–3) | I4: זיהוי עצמי | J4: דיוק ״אני יכול/ה״ | K4: שינוי: סוף מול תחילת שנה | L4: מגמה
A5: תלמיד לדוגמה | B5: =IF($A5="","",IFERROR(INDEX('זה אני - קליטה'!$AG$5:$AG$204,MATCH($A5&"|תחילת שנה",'זה אני - קליטה'!$Z$5:$Z$204,0)),"")) -> 1 | C5: =IF($A5="","",IFERROR(INDEX('זה אני - קליטה'!$AA$5:$AA$204,MATCH($A5&"|תחילת שנה",'זה אני - קליטה'!$Z$5:$Z$204,0)),"")) -> מלא | D5: =IF($A5="","",IFERROR(INDEX('זה אני - קליטה'!$AC$5:$AC$204,MATCH($A5&"|תחילת שנה",'זה אני - קליטה'!$Z$5:$Z$204,0)),"")) -> 0.5 | E5: =IF($A5="","",IFERROR(INDEX('זה אני - קליטה'!$AG$5:$AG$204,MATCH($A5&"|אמצע שנה",'זה אני - קליטה'!$Z$5:$Z$204,0)),"")) | F5: =IF($A5="","",IFERROR(INDEX('זה אני - קליטה'!$AA$5:$AA$204,MATCH($A5&"|אמצע שנה",'זה אני - קליטה'!$Z$5:$Z$204,0)),"")) | G5: =IF($A5="","",IFERROR(INDEX('זה אני - קליטה'!$AC$5:$AC$204,MATCH($A5&"|אמצע שנה",'זה אני - קליטה'!$Z$5:$Z$204,0)),"")) | H5: =IF($A5="","",IFERROR(INDEX('זה אני - קליטה'!$AG$5:$AG$204,MATCH($A5&"|סוף שנה",'זה אני - קליטה'!$Z$5:$Z$204,0)),"")) | I5: =IF($A5="","",IFERROR(INDEX('זה אני - קליטה'!$AA$5:$AA$204,MATCH($A5&"|סוף שנה",'זה אני - קליטה'!$Z$5:$Z$204,0)),"")) | J5: =IF($A5="","",IFERROR(INDEX('זה אני - קליטה'!$AC$5:$AC$204,MATCH($A5&"|סוף שנה",'זה אני - קליטה'!$Z$5:$Z$204,0)),"")) | K5: =IF(AND(ISNUMBER(B5),ISNUMBER(H5)),H5-B5,"") | L5: =IF(K5="","",IF(K5>=1,"עלייה",IF(K5<=-1,"ירידה","יציב")))
B6: =IF($A6="","",IFERROR(INDEX('זה אני - קליטה'!$AG$5:$AG$204,MATCH($A6&"|תחילת שנה",'זה אני - קליטה'!$Z$5:$Z$204,0)),"")) | C6: =IF($A6="","",IFERROR(INDEX('זה אני - קליטה'!$AA$5:$AA$204,MATCH($A6&"|תחילת שנה",'זה אני - קליטה'!$Z$5:$Z$204,0)),"")) | D6: =IF($A6="","",IFERROR(INDEX('זה אני - קליטה'!$AC$5:$AC$204,MATCH($A6&"|תחילת שנה",'זה אני - קליטה'!$Z$5:$Z$204,0)),"")) | E6: =IF($A6="","",IFERROR(INDEX('זה אני - קליטה'!$AG$5:$AG$204,MATCH($A6&"|אמצע שנה",'זה אני - קליטה'!$Z$5:$Z$204,0)),"")) | F6: =IF($A6="","",IFERROR(INDEX('זה אני - קליטה'!$AA$5:$AA$204,MATCH($A6&"|אמצע שנה",'זה אני - קליטה'!$Z$5:$Z$204,0)),"")) | G6: =IF($A6="","",IFERROR(INDEX('זה אני - קליטה'!$AC$5:$AC$204,MATCH($A6&"|אמצע שנה",'זה אני - קליטה'!$Z$5:$Z$204,0)),"")) | H6: =IF($A6="","",IFERROR(INDEX('זה אני - קליטה'!$AG$5:$AG$204,MATCH($A6&"|סוף שנה",'זה אני - קליטה'!$Z$5:$Z$204,0)),"")) | I6: =IF($A6="","",IFERROR(INDEX('זה אני - קליטה'!$AA$5:$AA$204,MATCH($A6&"|סוף שנה",'זה אני - קליטה'!$Z$5:$Z$204,0)),"")) | J6: =IF($A6="","",IFERROR(INDEX('זה אני - קליטה'!$AC$5:$AC$204,MATCH($A6&"|סוף שנה",'זה אני - קליטה'!$Z$5:$Z$204,0)),"")) | K6: =IF(AND(ISNUMBER(B6),ISNUMBER(H6)),H6-B6,"") | L6: =IF(K6="","",IF(K6>=1,"עלייה",IF(K6<=-1,"ירידה","יציב")))
B7: =IF($A7="","",IFERROR(INDEX('זה אני - קליטה'!$AG$5:$AG$204,MATCH($A7&"|תחילת שנה",'זה אני - קליטה'!$Z$5:$Z$204,0)),"")) | C7: =IF($A7="","",IFERROR(INDEX('זה אני - קליטה'!$AA$5:$AA$204,MATCH($A7&"|תחילת שנה",'זה אני - קליטה'!$Z$5:$Z$204,0)),"")) | D7: =IF($A7="","",IFERROR(INDEX('זה אני - קליטה'!$AC$5:$AC$204,MATCH($A7&"|תחילת שנה",'זה אני - קליטה'!$Z$5:$Z$204,0)),"")) | E7: =IF($A7="","",IFERROR(INDEX('זה אני - קליטה'!$AG$5:$AG$204,MATCH($A7&"|אמצע שנה",'זה אני - קליטה'!$Z$5:$Z$204,0)),"")) | F7: =IF($A7="","",IFERROR(INDEX('זה אני - קליטה'!$AA$5:$AA$204,MATCH($A7&"|אמצע שנה",'זה אני - קליטה'!$Z$5:$Z$204,0)),"")) | G7: =IF($A7="","",IFERROR(INDEX('זה אני - קליטה'!$AC$5:$AC$204,MATCH($A7&"|אמצע שנה",'זה אני - קליטה'!$Z$5:$Z$204,0)),"")) | H7: =IF($A7="","",IFERROR(INDEX('זה אני - קליטה'!$AG$5:$AG$204,MATCH($A7&"|סוף שנה",'זה אני - קליטה'!$Z$5:$Z$204,0)),"")) | I7: =IF($A7="","",IFERROR(INDEX('זה אני - קליטה'!$AA$5:$AA$204,MATCH($A7&"|סוף שנה",'זה אני - קליטה'!$Z$5:$Z$204,0)),"")) | J7: =IF($A7="","",IFERROR(INDEX('זה אני - קליטה'!$AC$5:$AC$204,MATCH($A7&"|סוף שנה",'זה אני - קליטה'!$Z$5:$Z$204,0)),"")) | K7: =IF(AND(ISNUMBER(B7),ISNUMBER(H7)),H7-B7,"") | L7: =IF(K7="","",IF(K7>=1,"עלייה",IF(K7<=-1,"ירידה","יציב")))
B8: =IF($A8="","",IFERROR(INDEX('זה אני - קליטה'!$AG$5:$AG$204,MATCH($A8&"|תחילת שנה",'זה אני - קליטה'!$Z$5:$Z$204,0)),"")) | C8: =IF($A8="","",IFERROR(INDEX('זה אני - קליטה'!$AA$5:$AA$204,MATCH($A8&"|תחילת שנה",'זה אני - קליטה'!$Z$5:$Z$204,0)),"")) | D8: =IF($A8="","",IFERROR(INDEX('זה אני - קליטה'!$AC$5:$AC$204,MATCH($A8&"|תחילת שנה",'זה אני - קליטה'!$Z$5:$Z$204,0)),"")) | E8: =IF($A8="","",IFERROR(INDEX('זה אני - קליטה'!$AG$5:$AG$204,MATCH($A8&"|אמצע שנה",'זה אני - קליטה'!$Z$5:$Z$204,0)),"")) | F8: =IF($A8="","",IFERROR(INDEX('זה אני - קליטה'!$AA$5:$AA$204,MATCH($A8&"|אמצע שנה",'זה אני - קליטה'!$Z$5:$Z$204,0)),"")) | G8: =IF($A8="","",IFERROR(INDEX('זה אני - קליטה'!$AC$5:$AC$204,MATCH($A8&"|אמצע שנה",'זה אני - קליטה'!$Z$5:$Z$204,0)),"")) | H8: =IF($A8="","",IFERROR(INDEX('זה אני - קליטה'!$AG$5:$AG$204,MATCH($A8&"|סוף שנה",'זה אני - קליטה'!$Z$5:$Z$204,0)),"")) | I8: =IF($A8="","",IFERROR(INDEX('זה אני - קליטה'!$AA$5:$AA$204,MATCH($A8&"|סוף שנה",'זה אני - קליטה'!$Z$5:$Z$204,0)),"")) | J8: =IF($A8="","",IFERROR(INDEX('זה אני - קליטה'!$AC$5:$AC$204,MATCH($A8&"|סוף שנה",'זה אני - קליטה'!$Z$5:$Z$204,0)),"")) | K8: =IF(AND(ISNUMBER(B8),ISNUMBER(H8)),H8-B8,"") | L8: =IF(K8="","",IF(K8>=1,"עלייה",IF(K8<=-1,"ירידה","יציב")))
B9: =IF($A9="","",IFERROR(INDEX('זה אני - קליטה'!$AG$5:$AG$204,MATCH($A9&"|תחילת שנה",'זה אני - קליטה'!$Z$5:$Z$204,0)),"")) | C9: =IF($A9="","",IFERROR(INDEX('זה אני - קליטה'!$AA$5:$AA$204,MATCH($A9&"|תחילת שנה",'זה אני - קליטה'!$Z$5:$Z$204,0)),"")) | D9: =IF($A9="","",IFERROR(INDEX('זה אני - קליטה'!$AC$5:$AC$204,MATCH($A9&"|תחילת שנה",'זה אני - קליטה'!$Z$5:$Z$204,0)),"")) | E9: =IF($A9="","",IFERROR(INDEX('זה אני - קליטה'!$AG$5:$AG$204,MATCH($A9&"|אמצע שנה",'זה אני - קליטה'!$Z$5:$Z$204,0)),"")) | F9: =IF($A9="","",IFERROR(INDEX('זה אני - קליטה'!$AA$5:$AA$204,MATCH($A9&"|אמצע שנה",'זה אני - קליטה'!$Z$5:$Z$204,0)),"")) | G9: =IF($A9="","",IFERROR(INDEX('זה אני - קליטה'!$AC$5:$AC$204,MATCH($A9&"|אמצע שנה",'זה אני - קליטה'!$Z$5:$Z$204,0)),"")) | H9: =IF($A9="","",IFERROR(INDEX('זה אני - קליטה'!$AG$5:$AG$204,MATCH($A9&"|סוף שנה",'זה אני - קליטה'!$Z$5:$Z$204,0)),"")) | I9: =IF($A9="","",IFERROR(INDEX('זה אני - קליטה'!$AA$5:$AA$204,MATCH($A9&"|סוף שנה",'זה אני - קליטה'!$Z$5:$Z$204,0)),"")) | J9: =IF($A9="","",IFERROR(INDEX('זה אני - קליטה'!$AC$5:$AC$204,MATCH($A9&"|סוף שנה",'זה אני - קליטה'!$Z$5:$Z$204,0)),"")) | K9: =IF(AND(ISNUMBER(B9),ISNUMBER(H9)),H9-B9,"") | L9: =IF(K9="","",IF(K9>=1,"עלייה",IF(K9<=-1,"ירידה","יציב")))
B10: =IF($A10="","",IFERROR(INDEX('זה אני - קליטה'!$AG$5:$AG$204,MATCH($A10&"|תחילת שנה",'זה אני - קליטה'!$Z$5:$Z$204,0)),"")) | C10: =IF($A10="","",IFERROR(INDEX('זה אני - קליטה'!$AA$5:$AA$204,MATCH($A10&"|תחילת שנה",'זה אני - קליטה'!$Z$5:$Z$204,0)),"")) | D10: =IF($A10="","",IFERROR(INDEX('זה אני - קליטה'!$AC$5:$AC$204,MATCH($A10&"|תחילת שנה",'זה אני - קליטה'!$Z$5:$Z$204,0)),"")) | E10: =IF($A10="","",IFERROR(INDEX('זה אני - קליטה'!$AG$5:$AG$204,MATCH($A10&"|אמצע שנה",'זה אני - קליטה'!$Z$5:$Z$204,0)),"")) | F10: =IF($A10="","",IFERROR(INDEX('זה אני - קליטה'!$AA$5:$AA$204,MATCH($A10&"|אמצע שנה",'זה אני - קליטה'!$Z$5:$Z$204,0)),"")) | G10: =IF($A10="","",IFERROR(INDEX('זה אני - קליטה'!$AC$5:$AC$204,MATCH($A10&"|אמצע שנה",'זה אני - קליטה'!$Z$5:$Z$204,0)),"")) | H10: =IF($A10="","",IFERROR(INDEX('זה אני - קליטה'!$AG$5:$AG$204,MATCH($A10&"|סוף שנה",'זה אני - קליטה'!$Z$5:$Z$204,0)),"")) | I10: =IF($A10="","",IFERROR(INDEX('זה אני - קליטה'!$AA$5:$AA$204,MATCH($A10&"|סוף שנה",'זה אני - קליטה'!$Z$5:$Z$204,0)),"")) | J10: =IF($A10="","",IFERROR(INDEX('זה אני - קליטה'!$AC$5:$AC$204,MATCH($A10&"|סוף שנה",'זה אני - קליטה'!$Z$5:$Z$204,0)),"")) | K10: =IF(AND(ISNUMBER(B10),ISNUMBER(H10)),H10-B10,"") | L10: =IF(K10="","",IF(K10>=1,"עלייה",IF(K10<=-1,"ירידה","יציב")))
